GTCEuStartupEvents.registry('gtceu:recipe_type', event => {
    event.create('mega_oreproc')
        .category('multiblocks')
        .setEUIO('in')
        .setMaxIOSize(2, 8, 1, 0) // Item Input, Output, Fluid Input, Output
        .setProgressBar(GuiTextures.PROGRESS_BAR_ARROW, FillDirection.LEFT_TO_RIGHT)
        .setSound(GTSoundEntries.MACERATOR)
})

GTCEuStartupEvents.registry('gtceu:machine', event => {
    event.create('mega_oreproc_facility', 'multiblock')
        .rotationState(RotationState.ALL)
        .recipeType('mega_oreproc')
        .recipeModifiers([GTRecipeModifiers.OC_PERFECT_SUBTICK, GTRecipeModifiers.BATCH_MODE])
        .appearanceBlock(() => Block.getBlock('kubejs:refracting_hastelloy_c276_casing'))
        .pattern(definition => FactoryBlockPattern.start()      
            .aisle("BBBBBBBBBBBBBBBBBBBBBBBBBBB", "BBBBBBBBBBBBBBBBBBBBBBBBBBB", "AAAAAAAAAAAAAAAAAAAAAAAAAAA", "AAAAAAAAAAAAAAAAAAAAAAAAAAA", "AAAAAAAAAAAAAAAAAAAAAAAAAAA", "AAAAAAAAAAAAAAAAAAAAAAAAAAA", "AAAAAAAAAAAAAAAAAAAAAAAAAAA", "AAAAAAAAAAAAAAAAAAAAAAAAAAA", "AAAAAAAAAAAAAAAAAAAAAAAAAAA", "AAAAAAAAAAAAAAAAAAAAAAAAAAA", "AAAAAAAAAAAAAAAAAAAAAAAAAAA", "AAAAAAAAAAAAAAAAAAAAAAAAAAA", "AAAAAAAAAAAAAAAAAAAAAAAAAAA", "AAAAAAAAAAAAAAAAAAAAAAAAAAA", "AAAAAAAAAAAAAAAAAAAAAAAAAAA")
            .aisle("BDDDDDDDDDDDDDDDDDDDDDDDDDB", "BDDDDDDDDDDDDDDDDDDDDDDDDDB", "AAAAAAAAAAAAAAAAAAAAAAAAAAA", "AAAAAAAAAAAAAAAAAAAAAAAAAAA", "AAAAAAAAAAAAAAAAAAAAAAAAAAA", "AAAAAAAAAAAAAAAAAAAAAAAAAAA", "AAAAAAAAAAAAAAAAAAAAAAAAAAA", "AAAAAAAAAAAAAAAAAAAAAAAAAAA", "AAAAAAAAAAAAAAAAAAAAAAAAAAA", "AAAAAAAAAAAAAAAAAAAAAAAAAAA", "AAAAAAAAAAAAAAAAAAAAAAAAAAA", "AAAAAAAAAAAAAAAAAAAAAAAAAAA", "AAAAAAAAAAAAAAAAAAAAAAAAAAA", "AAAAAAAAAAAAAAAAAAAAAAAAAAA", "AAAAAAAAAAAAAAAAAAAAAAAAAAA")
            .aisle("BDDDDDDDDDDDDDDDDDDDDDDDDDB", "BDDDDDDDDDDDDDDDDDDDDDDDDDB", "AAEAEEAEAEAEEAEAFFGGGGGFFAA", "AAEAGGAEAEAGGAEAFAAAGAAAFAA", "AAEAHHAEAEAHHAEAFAAAGAAAFAA", "AAEAHHAEAEAHHAEAFEEEEEEEFAA", "AAEAHHAEAEAHHAEAFFFIIIFFFAA", "AAEAHHAEAEAHHAEAFAAAAAAAFAA", "AAEAHHAEAEAHHAEAAAAAAAAAAAA", "AAEAHHAEAEAHHAEAAAAAAAAAAAA", "AAEAHHAEAEEFFEEAAAAAAAAAAAA", "AAEAHHAEAAAGGAAAAAAAAAAAAAA", "AAEAHHAEAAAAAAAAAAAAAAAAAAA", "AAEEHHEEAAAAAAAAAAAAAAAAAAA", "AAAAGGAAAAAAAAAAAAAAAAAAAAA")
            .aisle("BDDDDDDDDDDDDDDDDDDDDDDDDDB", "BDDDDDDDDDDDDDDDDDDDDDDDDDB", "AAAGJJGAAAGJJGAAFFFFFFFFFAA", "AAAGAAGAAAGAAGAAAKKKKKKKAAA", "AAAHAAHAAAHAAHAAAKKKKKKKAAA", "AAAHAAHAAAHAAHAAEKKKKKKKEAA", "AAAHAAHAAAHAAHAAFKKKKKKKFAA", "AAAHAAHAAAHAAHAAAKKKKKKKAAA", "AAAHAAHAAAHAEHAAALLALALLAAA", "AAAHAAHAAAHEAHAAAAAAAAAAAAA", "AAAHAAHAAEFMEFEAAAAAAAAAAAA", "AAAHAEHAAAGAAGAAAAAAAAAAAAA", "AAAHEAHAAAAAAAAAAAAAAAAAAAA", "AAEFMEFEAAAAAAAAAAAAAAAAAAA", "AAAGAAGAAAAAAAAAAAAAAAAAAAA")
            .aisle("BDDDDDDDDDDDDDDDDDDDDDDDDDB", "BDDDDDDDDDDDDDDDDDDDDDDDDDB", "AAEJJJJEAEJJJJEAGFFFFFFFGAA", "AAGAAAAGAGAAAAGAAKKKKKKKAAA", "AAHAAAAHAHAAAAHAAKNAAANKAAA", "AAHAAAAHAHAAAAHAEKAAAAAKEAA", "AAHAAAAHAHAAAAHAFKAANAAKFAA", "AAHAAAAHAHAAAAHAAKAAAAAKAAA", "AAHAAAAHAHEAEAHAALAALAALAAA", "AAHAAAAHAHAEAEHAAAAAAAAAAAA", "AAHAAAAHAFEMEMFAAAAAAAAAAAA", "AAHEAEAHAGAAAAGAAAAAAAAAAAA", "AAHAEAEHAAAAAAAAAAAAAAAAAAA", "AAFEMEMFAAAAAAAAAAAAAAAAAAA", "AAGAAAAGAAAAAAAAAAAAAAAAAAA")
            .aisle("BDDDDDDDDDDDDDDDDDDDDDDDDDB", "BDDDDDDDDDDDDDDDDDDDDDDDDDB", "AAEJJJJEAEJJJJEAGFFFFFFFGAA", "AAGAAAAGAGAAAAGAAKKKKKKKAAA", "AAHAAAAHAHAAAAHAAKANANAKAAA", "AAHAAAAHAHAAAAHAEKAAAAAKEAA", "AAHAAAAHAHAAAAHAIKAANAAKIAA", "AAHAAAAHAHAAAAHAAKAAAAAKAAA", "AAHAAAAHAHEAEAHAAAAALAAAAAA", "AAHAAAAHAHAEAEHAAAAAAAAAAAA", "AAHAAAAHAFEMEMFAAAAAAAAAAAA", "AAHEAEAHAGAAAAGAAAAAAAAAAAA", "AAHAEAEHAAAAAAAAAAAAAAAAAAA", "AAFEMEMFAAAAAAAAAAAAAAAAAAA", "AAGAAAAGAAAAAAAAAAAAAAAAAAA")
            .aisle("BDDDDDDDDDDDDDDDDDDDDDDDDDB", "BDDDDDDDDDDDDDDDDDDDDDDDDDB", "AAAGJJGAAAGJJGAAGFFFFFFFGAA", "AAAGAAGAAAGAAGAAGKKKKKKKGAA", "AAAHAAHAAAHAAHAAGKAAOAAKGAA", "AAAHAAHAAAHAAHAAEKAAOAAKEAA", "AAAHAAHAAAHAAHAAIKNNONNKIAA", "AAAHAAHAAAHAAHAAAKAAOAAKAAA", "AAAHAAHAAAHAEHAAALLLLLLLAAA", "AAAHAAHAAAHEAHAAAAAAAAAAAAA", "AAAHAAHAAEFMEFEAAAAAAAAAAAA", "AAAHAEHAAAGAAGAAAAAAAAAAAAA", "AAAHEAHAAAAAAAAAAAAAAAAAAAA", "AAEFMEFEAAAAAAAAAAAAAAAAAAA", "AAAGAAGAAAAAAAAAAAAAAAAAAAA")
            .aisle("BDDDDDDDDDDDDDDDDDDDDDDDDDB", "BDDDDDDDDDDDDDDDDDDDDDDDDDB", "AAEAEEAEAEAEEAEAGFFFFFFFGAA", "AAEAGGAEAEAGGAEAAKKKKKKKAAA", "AAEAHHAEAEAHHAEAAKANANAKAAA", "AAEAHHAEAEAHHAEAEKAAAAAKEAA", "AAEAHHAEAEAHHAEAIKAANAAKIAA", "AAEAHHAEAEAHHAEAAKAAAAAKAAA", "AAEAHHAEAEAHHAEAAAAALAAAAAA", "AAEAHHAEAEAHHAEAAAAAAAAAAAA", "AAEAHHAEAEEFFEEAAAAAAAAAAAA", "AAEAHHAEAAAGGAAAAAAAAAAAAAA", "AAEAHHAEAAAAAAAAAAAAAAAAAAA", "AAEEFFEEAAAAAAAAAAAAAAAAAAA", "AAAAGGAAAAAAAAAAAAAAAAAAAAA")
            .aisle("BDDDDDDDDDDDDDDDDDDDDDDDDDB", "BDDDDDDDDDDDDDDDDDDDDDDDDDB", "AAAAAAAAAAAAAAAAGFFFFFFFGAA", "AAAAAAAAAAAAAAAAAKKKKKKKAAA", "AAAAAAAAAAAAAAAAAKNAAANKAAA", "AAAAAAAAAAAAAAAAEKAAAAAKEAA", "AAAAAAAAAAAAAAAAFKAANAAKFAA", "AAAAAAAAAAAAAAAAAKAAAAAKAAA", "AAAAAAAAAAAAAAAAALAALAALAAA", "AAAAAAAAAAAAAAAAAAAAAAAAAAA", "AAAAAAAAAAAAAAAAAAAAAAAAAAA", "AAAAAAAAAAAAAAAAAAAAAAAAAAA", "AAAAAAAAAAAAAAAAAAAAAAAAAAA", "AAAAAAAAAAAAAAAAAAAAAAAAAAA", "AAAAAAAAAAAAAAAAAAAAAAAAAAA")
            .aisle("BDDDDDDDDDDDDDDDDDDDDDDDDDB", "BDDDDDDDDDDDDDDDDDDDDDDDDDB", "AAAGGGGGGGGGAAAAFFFFFFFFFAA", "AAAAAEAEAEAAAAAAAKKKKKKKAAA", "AAAAAEAEAEAAAAAAAKKKKKKKAAA", "AAAAAAEEEAAAAAAAEKKKKKKKEAA", "AAAAAAAAAAAAAAAAFKKKKKKKFAA", "AAAAAAAAAAAAAAAAAKKKKKKKAAA", "AAAAAAAAAAAAAAAAALLALALLAAA", "AAAAAAAAAAAAAAAAAAAAAAAAAAA", "AAAAAAAAAAAAAAAAAAAAAAAAAAA", "AAAAAAAAAAAAAAAAAAAAAAAAAAA", "AAAAAAAAAAAAAAAAAAAAAAAAAAA", "AAAAAAAAAAAAAAAAAAAAAAAAAAA", "AAAAAAAAAAAAAAAAAAAAAAAAAAA")
            .aisle("BDDDDDDDDDDDDDDDDDDDDDDDDDB", "BDDDDDDDDDDDDDDDDDDDDDDDDDB", "AAGGGGGGGGGGGAAAFFGGGGGFFAA", "AAAAPPPPPPPAAAAAFAAAGAAAFAA", "AAAAPPPPPPPAAAAAFAAAGAAAFAA", "AAAAAPPPPPAAAAAAFEEEEEEEFAA", "AAAAAAPPPAAAAAAAFFFIIIFFFAA", "AAAAAAAAAAAAAAAAFAAAAAAAFAA", "AAAAAAAAAAAAAAAAAAAAAAAAAAA", "AAAAAAAAAAAAAAAAAAAAAAAAAAA", "AAAAAAAAAAAAAAAAAAAAAAAAAAA", "AAAAAAAAAAAAAAAAAAAAAAAAAAA", "AAAAAAAAAAAAAAAAAAAAAAAAAAA", "AAAAAAAAAAAAAAAAAAAAAAAAAAA", "AAAAAAAAAAAAAAAAAAAAAAAAAAA")
            .aisle("BDDDDDDDDDDDDDDDDDDDDDDDDDB", "BDDDDDDDDDDDDDDDDDDDDDDDDDB", "AAGGGGGGGGGGGAAAAAAAMAAAAAA", "AAAPAAAAAAAPAAAAAAAAMAAAAAA", "AAAPAAAAAAAPAAAAAAAAQAAAAAA", "AAAAPARPRAPAAAAAAAAAAAAAAAA", "AAAAPPAIAPPAAAAAAAAAAAAAAAA", "AAAAAAAAAAAAAAAAAAAAAAAAAAA", "AAAAAAAAAAAAAAAAAAAAAAAAAAA", "AAAAAAAAAAAAAAAAAAAAAAAAAAA", "AAAAAAAAAAAAAAAAAAAAAAAAAAA", "AAAAAAAAAAAAAAAAAAAAAAAAAAA", "AAAAAAAAAAAAAAAAAAAAAAAAAAA", "AAAAAAAAAAAAAAAAAAAAAAAAAAA", "AAAAAAAAAAAAAAAAAAAAAAAAAAA")
            .aisle("BDDDDDDDDDDDDDDDDDDDDDDDDDB", "BDDDDDDDDDDDDDDDDDDDDDDDDDB", "AAGGGGGGGGGGGAFAAAFFFAAAFAA", "AAEPAAAAAAAPEAFFFFFFFFFFFAA", "AAEPAAAAAAAPEAFEEEFFQEEEFAA", "AAAPARRPRRPPAAAESEATAESEAAA", "AAAAPAAIAAPAAAASSSATASSSAAA", "AAAAAAAAAAAAAAASSSTTTSSSAAA", "AAAAAAAAAAAAAAASSSATASSSAAA", "AAAAAAAAAAAAAAAASAATAASAAAA", "AAAAAAAAAAAAAAAAAAAAAAAAAAA", "AAAAAAAAAAAAAAAAAAAAAAAAAAA", "AAAAAAAAAAAAAAAAAAAAAAAAAAA", "AAAAAAAAAAAAAAAAAAAAAAAAAAA", "AAAAAAAAAAAAAAAAAAAAAAAAAAA")
            .aisle("BDDDDDDDDDDDDDDDDDDDDDDDDDB", "BDDDDDDDDDDDDDDDDDDDDDDDDDB", "AAGGGGGGGGGGGAAJJJJJJJJJAAA", "AAAPAAAAAAAPAAFAAAFAFAAAFAA", "AAAPAAAAAAAPAAAASAATQASAAAA", "AAEPRRRPRRRPEAASASAAASASAAA", "AAAPAAAIAAAPAASAAASASAAASAA", "AAAAAAAAAAAAAASEOESASEOESAA", "AAAAAAAAAAAAAASAAASASAAASAA", "AAAAAAAAAAAAAAASASAAASASAAA", "AAAAAAAAAAAAAAAASTTTTTSAAAA", "AAAAAAAAAAAAAAAAAAAAAAAAAAA", "AAAAAAAAAAAAAAAAAAAAAAAAAAA", "AAAAAAAAAAAAAAAAAAAAAAAAAAA", "AAAAAAAAAAAAAAAAAAAAAAAAAAA")
            .aisle("BDDDDDDDDDDDDDDDDDDDDDDDDDB", "BDDDDDDDDDDDDDDDDDDDDDDDDDB", "AAGGGGGGGGGGGAAJJJJJJJJJAAA", "AAEPAAAAAAAPEAFASAFTFASAFAA", "AAEPAAAAAAAPEAASASAAQSASAAA", "AAEPRRRPRRRPEASEOESASEOESAA", "AAAPAAAIAAAPAASAAASASAAASAA", "AAAPIIIIIIIPAASEOESASEOESAA", "AAAAAAAAAAAAAASAAASASAAASAA", "AAAAAAAAAAAAAASEOESASEOESAA", "AAAAAAAAAAAAAAASASAAASASAAA", "AAAAAAAAAAAAAAAASAATAASAAAA", "AAAAAAAAAAAAAAAAAAAAAAAAAAA", "AAAAAAAAAAAAAAAAAAAAAAAAAAA", "AAAAAAAAAAAAAAAAAAAAAAAAAAA")
            .aisle("BDDDDDDDDDDDDDDDDDDDDDDDDDB", "BDDDDDDDDDDDDDDDDDDDDDDDDDB", "AAGGGGGGGGGGGAAJJJJJJJJJAAA", "AAAPAAAAAAAPAAFSSSFTFSSSFAA", "AAAPAAAAAAAPAASAAASASAAASAA", "AAEPRRRPRRRPEASAAASASAAASAA", "AAAPAAAIAAAPAASEOESASEOESAA", "AAAAAAAAAAAAAASEOESESEOESAA", "AAAAAAAAAAAAAASEOESASEOESAA", "AAAAAAAAAAAAAASAAASASAAASAA", "AAAAAAAAAAAAAASAAASASAAASAA", "AAAAAAAAAAAAAAASSSATASSSAAA", "AAAAAAAAAAAAAAAAAAAAAAAAAAA", "AAAAAAAAAAAAAAAAAAAAAAAAAAA", "AAAAAAAAAAAAAAAAAAAAAAAAAAA")
            .aisle("BDDDDDDDDDDDDDDDDDDDDDDDDDB", "BDDDDDDDDDDDDDDDDDDDDDDDDDB", "AAGGGGGGGGGGGAAJJJJJJJJJAAA", "AAEPAAAAAAAPEAFSSSTTTSSSFAA", "AAEPAAAAAAAPEASEOESASEOESAA", "AAAPARRPRRAPAASEOESASEOESAA", "AAAAPAAIAAPAAASEOESESEOESAA", "AAAAAAAAAAAAAAUGGGGGGGGGUAA", "AAAAAAAAAAAAAASEOESESEOESAA", "AAAAAAAAAAAAAASEOESASEOESAA", "AAAAAAAAAAAAAASEOESASEOESAA", "AAAAAAAAAAAAAAASSSTTTSSSAAA", "AAAAAAAAAAAAAAAAAAAAAAAAAAA", "AAAAAAAAAAAAAAAAAAAAAAAAAAA", "AAAAAAAAAAAAAAAAAAAAAAAAAAA")
            .aisle("BDDDDDDDDDDDDDDDDDDDDDDDDDB", "BDDDDDDDDDDDDDDDDDDDDDDDDDB", "AAGGGGGGGGGGGAAJJJJJJJJJAAA", "AAAPAAAAAAAPAAFSSSFTFSSSFAA", "AAAPAAAAAAAPAASAAASASAAASAA", "AAAAPPRPRAPAAASAAASASAAASAA", "AAAAPPAIAPPAAASEOESASEOESAA", "AAAAAAAAAAAAAASEOESESEOESAA", "AAAAAAAAAAAAAASEOESASEOESAA", "AAAAAAAAAAAAAASAAASASAAASAA", "AAAAAAAAAAAAAASAAASASAAASAA", "AAAAAAAAAAAAAAASSSATASSSAAA", "AAAAAAAAAAAAAAAAAAAAAAAAAAA", "AAAAAAAAAAAAAAAAAAAAAAAAAAA", "AAAAAAAAAAAAAAAAAAAAAAAAAAA")
            .aisle("BDDDDDDDDDDDDDDDDDDDDDDDDDB", "BDDDDDDDDDDDDDDDDDDDDDDDDDB", "AAGGGGGGGGGGGAAJJJJJJJJJAAA", "AAAAPPPPPPPAAAFASAFTFASAFAA", "AAAAPPPPPPPAAAASASAAASASAAA", "AAAAAPPPPPAAAASEOESASEOESAA", "AAAAAAPPPAAAAASAAASASAAASAA", "AAAAAAAAAAAAAASEOESASEOESAA", "AAAAAAAAAAAAAASAAASASAAASAA", "AAAAAAAAAAAAAASEOESASEOESAA", "AAAAAAAAAAAAAAASASAAASASAAA", "AAAAAAAAAAAAAAAASAATAASAAAA", "AAAAAAAAAAAAAAAAAAAAAAAAAAA", "AAAAAAAAAAAAAAAAAAAAAAAAAAA", "AAAAAAAAAAAAAAAAAAAAAAAAAAA")
            .aisle("BDDDDDDDDDDDDDDDDDDDDDDDDDB", "BDDDDDDDDDDDDDDDDDDDDDDDDDB", "AAAGGGGGGGGGAAAJJJJJJJJJAAA", "AAAAAEAEAEAAAAFAAAFAFAAAFAA", "AAAAAEAEAEAAAAAASAATAASAAAA", "AAAAAAEQEAAAAAASASAAASASAAA", "AAAAAAAAAAAAAASAAASASAAASAA", "AAAAAAAAAAAAAASEOESASEOESAA", "AAAAAAAAAAAAAASAAASASAAASAA", "AAAAAAAAAAAAAAASASAAASASAAA", "AAAAAAAAAAAAAAAASTTTTTSAAAA", "AAAAAAAAAAAAAAAAAAAAAAAAAAA", "AAAAAAAAAAAAAAAAAAAAAAAAAAA", "AAAAAAAAAAAAAAAAAAAAAAAAAAA", "AAAAAAAAAAAAAAAAAAAAAAAAAAA")
            .aisle("BDDDDDDDDDDDDDDDDDDDDDDDDDB", "BDDDDDDDDDDDDDDDDDDDDDDDDDB", "AAAAAAAMAAAAAAFAAAFFFAAAFAA", "AAAAAAAMAAAAAAFFFFFFFFFFFAA", "AAAAAAAMAAAAAAFEEEFFFEEEFAA", "AAAAAAAQAAAAAAAESEATAESEAAA", "AAAAAAAAAAAAAAASSSATASSSAAA", "AAAAAAAAAAAAAAASSSTTTSSSAAA", "AAAAAAAAAAAAAAASSSATASSSAAA", "AAAAAAAAAAAAAAAASAATAASAAAA", "AAAAAAAAAAAAAAAAAAAAAAAAAAA", "AAAAAAAAAAAAAAAAAAAAAAAAAAA", "AAAAAAAAAAAAAAAAAAAAAAAAAAA", "AAAAAAAAAAAAAAAAAAAAAAAAAAA", "AAAAAAAAAAAAAAAAAAAAAAAAAAA")
            .aisle("BDDDDDDDDDDDDDDDDDDDDDDDDDB", "BDDDDDDDDDDDDDDDDDDDDDDDDDB", "AAAAAAAAAAAAAAAAMAAAAAAAAAA", "AAAAAAAAAAAAAAAAMAAAAAAAAAA", "AAAAAAAMAAAAAAAAMAAAAAAAAAA", "AAAAAAAQAAAAAAAAMAAAAAAAAAA", "AAAAAAAAAAAAAAAAMAAAAAAAAAA", "AAAAAAAAAAAAAAAAQAAAAAAAAAA", "AAAAAAAAAAAAAAAAAAAAAAAAAAA", "AAAAAAAAAAAAAAAAAAAAAAAAAAA", "AAAAAAAAAAAAAAAAAAAAAAAAAAA", "AAAAAAAAAAAAAAAAAAAAAAAAAAA", "AAAAAAAAAAAAAAAAAAAAAAAAAAA", "AAAAAAAAAAAAAAAAAAAAAAAAAAA", "AAAAAAAAAAAAAAAAAAAAAAAAAAA")
            .aisle("BDDDDDDDDDDDDDDDDDDDDDDDDDB", "BDDDDDDDDDDDDDDDDDDDDDDDDDB", "AAAGGGEEEGGGAAAAAAGEEEEEGAA", "AAAGAGAMAGAGAAAAAAGGGGGGGAA", "AAAGAGAMAGAGAAAAAAAVAAAVAAA", "AAAGAGAQAGAGAAAAAAAVAAAVAAA", "AAAGAGAAAGAGAAAAMAAVAAAVAAA", "AAAGAGAAAGAGAAAAQAAVAAAVAAA", "AAAGAGEEEGAGAAAAAAAAAAAAAAA", "AAAAAAAAAAAAAAAAAAAAAAAAAAA", "AAAAAAAAAAAAAAAAAAAAAAAAAAA", "AAAAAAAAAAAAAAAAAAAAAAAAAAA", "AAAAAAAAAAAAAAAAAAAAAAAAAAA", "AAAAAAAAAAAAAAAAAAAAAAAAAAA", "AAAAAAAAAAAAAAAAAAAAAAAAAAA")
            .aisle("BDDDDDDDDDDDDDDDDDDDDDDDDDB", "BDDDDDDDDDDDDDDDDDDDDDDDDDB", "AAWWWWWWWWWWWAAAMGFFFFFFFGA", "AAWWXWWWWWXWWAAAMGFFFFFFFGA", "AAWWXWWYWWXWWAAAMAZZZZZZZAA", "AAWWXWWWWWXWWAAAMAZZZZZZZAA", "AAWWXWWYWWXWWAAAMAZZZZZZZAA", "AAWWXWWWWWXWWAAAQAAVAAAVAAA", "AAAGAGAAAGAGAAAAAAAAAAAAAAA", "AAAAAAAAAAAAAAAAAAAAAAAAAAA", "AAAAAAAAAAAAAAAAAAAAAAAAAAA", "AAAAAAAAAAAAAAAAAAAAAAAAAAA", "AAAAAAAAAAAAAAAAAAAAAAAAAAA", "AAAAAAAAAAAAAAAAAAAAAAAAAAA", "AAAAAAAAAAAAAAAAAAAAAAAAAAA")
            .aisle("BDDDDDDDDDDDDDDDDDDDDDDDDDB", "BDDDDDDDDDDDDDDDDDDDDDDDDDB", "AEWWWWWWWWWWWEAAAEFFFFFFFEA", "AEI[GWXAXWG[IEAAAGFJJJJJFGA", "AEW[GWXAXWG[WEAAAVZEEEEEZVA", "AEW[GWXAXWG[WEAAAVZEEEEEZVA", "AEW[GWXAXWG[WEAAMVZZZZZZZVA", "AAW[XWWWWWX[WAAAQVVVVVVVVVA", "AAAGAGAAAGAGAAAAAAAAAAAAAAA", "AAAAAAAAAAAAAAAAAAAAAAAAAAA", "AAAAAAAAAAAAAAAAAAAAAAAAAAA", "AAAAAAAAAAAAAAAAAAAAAAAAAAA", "AAAAAAAAAAAAAAAAAAAAAAAAAAA", "AAAAAAAAAAAAAAAAAAAAAAAAAAA", "AAAAAAAAAAAAAAAAAAAAAAAAAAA")
            .aisle("BDDDDDDDDDDDDDDDDDDDDDDDDDB", "BDDDDDDDDDDDDDDDDDDDDDDDDDB", "AAWWWWWWWWWWWAAAMEFFFFFFFEA", "AAI[GW[A[WG[IAAAMGFJJJJJFGA", "AAW[GW[A[WG[QAAAMAZAAAAAZAA", "AAW[GW[A[WG[QAAAMAZAAAAAZAA", "AAW[GW[A[WG[QAAAMAZ@@Z@@ZAA", "AAW[XWWWWWX[WAAAQAAAAVAAAAA", "AAAGAGAAAGAGAAAAAAAAAAAAAAA", "AAAAAAAAAAAAAAAAAAAAAAAAAAA", "AAAAAAAAAAAAAAAAAAAAAAAAAAA", "AAAAAAAAAAAAAAAAAAAAAAAAAAA", "AAAAAAAAAAAAAAAAAAAAAAAAAAA", "AAAAAAAAAAAAAAAAAAAAAAAAAAA", "AAAAAAAAAAAAAAAAAAAAAAAAAAA")
            .aisle("BDDDDDDDDDDDDDDDDDDDDDDDDDB", "BDDDDDDDDDDDDDDDDDDDDDDDDDB", "AAWWWWWWWWWWWMAAMEFFFFFFFEA", "AAI[GWXAXWG[IMAAMGFJJJJJFGA", "AAW[GWXAXWG[QMMMMMZEEEEEZAA", "AAW[GWXAXWG[QQQQQQZEEEEEZAA", "AAW[GWXAXWG[QAAAQAZ@@Z@@ZAA", "AAW[XWWWWWX[WAAAQAAAAVAAAAA", "AAAGAGEEEGAGAAAAAAAAAAAAAAA", "AAAAAAAAAAAAAAAAAAAAAAAAAAA", "AAAAAAAAAAAAAAAAAAAAAAAAAAA", "AAAAAAAAAAAAAAAAAAAAAAAAAAA", "AAAAAAAAAAAAAAAAAAAAAAAAAAA", "AAAAAAAAAAAAAAAAAAAAAAAAAAA", "AAAAAAAAAAAAAAAAAAAAAAAAAAA")
            .aisle("BDDDDDDDDDDDDDDDDDDDDDDDDDB", "BDDDDDDDDDDDDDDDDDDDDDDDDDB", "AAWWWWWWWWWWWAAAAEFFFFFFFEA", "AAI[GW[A[WG[IAAAAGFJJJJJFGA", "AAW[GW[A[WG[QAAAAAZAAAAAZAA", "AAW[GW[A[WG[QAAAAAZAAAAAZAA", "AAW[GW[A[WG[QAAAAAZ@@Z@@ZAA", "AAW[XWWWWWX[WAAAAAAAAVAAAAA", "AAAGAGAAAGAGAAAAAAAAAAAAAAA", "AAAAAAAAAAAAAAAAAAAAAAAAAAA", "AAAAAAAAAAAAAAAAAAAAAAAAAAA", "AAAAAAAAAAAAAAAAAAAAAAAAAAA", "AAAAAAAAAAAAAAAAAAAAAAAAAAA", "AAAAAAAAAAAAAAAAAAAAAAAAAAA", "AAAAAAAAAAAAAAAAAAAAAAAAAAA")
            .aisle("BDDDDDDDDDDDDDDDDDDDDDDDDDB", "BDDDDDDDDDDDDDDDDDDDDDDDDDB", "AEWWWWWWWWWWWEAAAEFFFFFFFEA", "AEI[GWXAXWG[IEAAAGFJJJJJFGA", "AEW[GWXAXWG[WEAAAVZEEEEEZVA", "AEW[GWXAXWG[WEAAAVZEEEEEZVA", "AEW[GWXAXWG[WEAAAVZZZZZZZVA", "AAW[XWWWWWX[WAAAAVVVVVVVVVA", "AAAGAGAAAGAGAAAAAAAAAAAAAAA", "AAAAAAAAAAAAAAAAAAAAAAAAAAA", "AAAAAAAAAAAAAAAAAAAAAAAAAAA", "AAAAAAAAAAAAAAAAAAAAAAAAAAA", "AAAAAAAAAAAAAAAAAAAAAAAAAAA", "AAAAAAAAAAAAAAAAAAAAAAAAAAA", "AAAAAAAAAAAAAAAAAAAAAAAAAAA")
            .aisle("BDDDDDDDDDDDDDDDDDDDDDDDDDB", "BDDDDDDDDDDDDDDDDDDDDDDDDDB", "AAWWWWWWWWWWWAAAAGFFFFFFFGA", "AAWWXWWWWWXWWAAAAGFFFFFFFGA", "AAWWXWWYWWXWWAAAAAZZZZZZZAA", "AAWWXWWWWWXWWAAAAAZZZ]ZZZAA", "AAWWXWWYWWXWWAAAAAZZZZZZZAA", "AAWWXWWWWWXWWAAAAAAVAAAVAAA", "AAAGAGAAAGAGAAAAAAAAAAAAAAA", "AAAAAAAAAAAAAAAAAAAAAAAAAAA", "AAAAAAAAAAAAAAAAAAAAAAAAAAA", "AAAAAAAAAAAAAAAAAAAAAAAAAAA", "AAAAAAAAAAAAAAAAAAAAAAAAAAA", "AAAAAAAAAAAAAAAAAAAAAAAAAAA", "AAAAAAAAAAAAAAAAAAAAAAAAAAA")
            .aisle("BDDDDDDDDDDDDDDDDDDDDDDDDDB", "BDDDDDDDDDDDDDDDDDDDDDDDDDB", "AAAGGGEEEGGGAAAAAAGEEEEEGAA", "AAAGAGAAAGAGAAAAAAGGGGGGGAA", "AAAGAGAAAGAGAAAAAAAVAAAVAAA", "AAAGAGAAAGAGAAAAAAAVAAAVAAA", "AAAGAGAAAGAGAAAAAAAVAAAVAAA", "AAAGAGAAAGAGAAAAAAAVAAAVAAA", "AAAGAGEEEGAGAAAAAAAAAAAAAAA", "AAAAAAAAAAAAAAAAAAAAAAAAAAA", "AAAAAAAAAAAAAAAAAAAAAAAAAAA", "AAAAAAAAAAAAAAAAAAAAAAAAAAA", "AAAAAAAAAAAAAAAAAAAAAAAAAAA", "AAAAAAAAAAAAAAAAAAAAAAAAAAA", "AAAAAAAAAAAAAAAAAAAAAAAAAAA")
            .aisle("BBBBBBBBBBBBBBBBBBBBBBBBBBB", "BBBBBBBBBBBBBBBBBBBBBBBBBBB", "AAAAAAAAAAAAAAAAAAAAAAAAAAA", "AAAAAAAAAAAAAAAAAAAAAAAAAAA", "AAAAAAAAAAAAAAAAAAAAAAAAAAA", "AAAAAAAAAAAAAAAAAAAAAAAAAAA", "AAAAAAAAAAAAAAAAAAAAAAAAAAA", "AAAAAAAAAAAAAAAAAAAAAAAAAAA", "AAAAAAAAAAAAAAAAAAAAAAAAAAA", "AAAAAAAAAAAAAAAAAAAAAAAAAAA", "AAAAAAAAAAAAAAAAAAAAAAAAAAA", "AAAAAAAAAAAAAAAAAAAAAAAAAAA", "AAAAAAAAAAAAAAAAAAAAAAAAAAA", "AAAAAAAAAAAAAAAAAAAAAAAAAAA", "AAAAAAAAAAAAAAAAAAAAAAAAAAA")
                .where("A", Predicates.any())
                .where("]", Predicates.controller(Predicates.blocks(definition.get())))
                .where("B", Predicates.blocks("kubejs:orbital_space_containment_casing"))
                .where("D", Predicates.blocks("kubejs:reinforced_base_casing"))
                .where("E", Predicates.blocks("gtceu:cosmic_neutronium_frame"))
                .where("F", Predicates.blocks("gtceu:high_temperature_smelting_casing"))
                .where("G", Predicates.blocks("kubejs:covalent_conducting_casing"))
                .where("H", Predicates.blocks("gtceu:stainless_steel_turbine_casing"))
                .where("I", Predicates.blocks("gtceu:hsla_steel_frame"))
                .where("J", Predicates.blocks("gtceu:heat_vent"))
                .where("K", Predicates.blocks("gtceu:watertight_casing"))
                .where("L", Predicates.blocks("gtceu:watertight_steel_frame"))
                .where("M", Predicates.blocks("gtceu:neutronium_frame"))
                .where("N", Predicates.blocks("gtceu:titanium_pipe_casing"))
                .where("O", Predicates.blocks("gtceu:steel_pipe_casing"))
                .where("P", Predicates.blocks("gtceu:corrosion_proof_casing"))
                .where("Q", Predicates.blocks("kubejs:neutronium_casing"))
                .where("R", Predicates.blocks("gtceu:assembly_line_grating"))
                .where("S", Predicates.blocks("gtceu:vibration_safe_casing"))
                .where("T", Predicates.blocks("gtceu:incoloy_ma_956_frame"))
                .where("U", Predicates.abilities(PartAbility.MUFFLER))
                .where("V", Predicates.blocks("gtceu:hastelloy_c_276_frame"))
                .where("W", Predicates.blocks("gtceu:nonconducting_casing"))
                .where("X", Predicates.blocks("gtceu:electrolytic_cell"))
                .where("Y", Predicates.blocks("antiblocksrechiseled:bright_white_border"))
                .where("[", Predicates.blocks("kubejs:highly_superconducting_coil_block"))
                .where("@", Predicates.blocks("kubejs:orbital_solar_casing"))
                .where("Z", Predicates.blocks("kubejs:refracting_hastelloy_c276_casing")
                    .or(Predicates.abilities(
                        PartAbility.EXPORT_ITEMS,
                        PartAbility.IMPORT_ITEMS,
                        PartAbility.INPUT_LASER,
                        PartAbility.INPUT_ENERGY,
                        PartAbility.IMPORT_FLUIDS,
                        PartAbility.EXPORT_FLUIDS))
                )
            .build()
        )
        .workableCasingModel("kubejs:block/casings/refracting_hastelloy_c276_casing", 'kubejs:block/gui/machine_controller/mega_oreproc_facility')
})
