GTCEuStartupEvents.registry('gtceu:recipe_type', event => {
    event.create('distillation_facility')
        .category('multiblocks')
        .setEUIO('in')
        .setMaxIOSize(2, 0, 3, 18) // Item Input, Output, Fluid Input, Output
        .setProgressBar(GuiTextures.PROGRESS_BAR_ARROW, FillDirection.LEFT_TO_RIGHT)
        .setSound(GTSoundEntries.MACERATOR)
})

GTCEuStartupEvents.registry('gtceu:machine', event => {
    event.create('distillation_facility_complex', 'multiblock')
        .rotationState(RotationState.ALL)
        .recipeType('distillation_facility')
        .recipeModifiers([GTRecipeModifiers.OC_PERFECT_SUBTICK, GTRecipeModifiers.BATCH_MODE])
        .appearanceBlock(() => Block.getBlock('kubejs:supercritical_cryo_cooled_casing'))
        .pattern(definition => FactoryBlockPattern.start()
            .aisle("BBBBBBBBBBBBBBBBBBBBBBBBBBB", "BBBBBBBBBBBBBBBBBBBBBBBBBBB", "AAAAAAAAAAAAAAAAAAAAAAAAAAA", "AAAAAAAAAAAAAAAAAAAAAAAAAAA", "AAAAAAAAAAAAAAAAAAAAAAAAAAA", "AAAAAAAAAAAAAAAAAAAAAAAAAAA", "AAAAAAAAAAAAAAAAAAAAAAAAAAA", "AAAAAAAAAAAAAAAAAAAAAAAAAAA", "AAAAAAAAAAAAAAAAAAAAAAAAAAA", "AAAAAAAAAAAAAAAAAAAAAAAAAAA", "AAAAAAAAAAAAAAAAAAAAAAAAAAA", "AAAAAAAAAAAAAAAAAAAAAAAAAAA", "AAAAAAAAAAAAAAAAAAAAAAAAAAA", "AAAAAAAAAAAAAAAAAAAAAAAAAAA", "AAAAAAAAAAAAAAAAAAAAAAAAAAA", "AAAAAAAAAAAAAAAAAAAAAAAAAAA", "AAAAAAAAAAAAAAAAAAAAAAAAAAA", "AAAAAAAAAAAAAAAAAAAAAAAAAAA", "AAAAAAAAAAAAAAAAAAAAAAAAAAA", "AAAAAAAAAAAAAAAAAAAAAAAAAAA", "AAAAAAAAAAAAAAAAAAAAAAAAAAA", "AAAAAAAAAAAAAAAAAAAAAAAAAAA", "AAAAAAAAAAAAAAAAAAAAAAAAAAA", "AAAAAAAAAAAAAAAAAAAAAAAAAAA", "AAAAAAAAAAAAAAAAAAAAAAAAAAA", "AAAAAAAAAAAAAAAAAAAAAAAAAAA")
            .aisle("BDDDDDDDDDDDDDDDDDDDDDDDDDB", "BDDDDDDDDDDDDDDDDDDDDDDDDDB", "AAAAAAAAAAAAAAAAAAAAAAAAAAA", "AAAAAAAAAAAAAAAAAAAAAAAAAAA", "AAAAAAAAAAAAAAAAAAAAAAAAAAA", "AAAAAAAAAAAAAAAAAAAAAAAAAAA", "AAAAAAAAAAAAAAAAAAAAAAAAAAA", "AAAAAAAAAAAAAAAAAAAAAAAAAAA", "AAAAAAAAAAAAAAAAAAAAAAAAAAA", "AAAAAAAAAAAAAAAAAAAAAAAAAAA", "AAAAAAAAAAAAAAAAAAAAAAAAAAA", "AAAAAAAAAAAAAAAAAAAAAAAAAAA", "AAAAAAAAAAAAAAAAAAAAAAAAAAA", "AAAAAAAAAAAAAAAAAAAAAAAAAAA", "AAAAAAAAAAAAAAAAAAAAAAAAAAA", "AAAAAAAAAAAAAAAAAAAAAAAAAAA", "AAAAAAAAAAAAAAAAAAAAAAAAAAA", "AAAAAAAAAAAAAAAAAAAAAAAAAAA", "AAAAAAAAAAAAAAAAAAAAAAAAAAA", "AAAAAAAAAAAAAAAAAAAAAAAAAAA", "AAAAAAAAAAAAAAAAAAAAAAAAAAA", "AAAAAAAAAAAAAAAAAAAAAAAAAAA", "AAAAAAAAAAAAAAAAAAAAAAAAAAA", "AAAAAAAAAAAAAAAAAAAAAAAAAAA", "AAAAAAAAAAAAAAAAAAAAAAAAAAA", "AAAAAAAAAAAAAAAAAAAAAAAAAAA")
            .aisle("BDDDDDDDDDDDDDDDDDDDDDDDDDB", "BDDDDDDDDDDDDDDDDDDDDDDDDDB", "AAAAAAAAAEFGFEAAAAAAAAAAAAA", "AAAAAAAAAEFGFEAAAAAAAAAAAAA", "AAAAAAAAAEFGFEAAAAAAAAAAAAA", "AAAAAAAAAEFGFEAAAAAAAAAAAAA", "AAAAAAAAAEFGFEAAAAAAAAAAAAA", "AAAAAAAAAEFGFEAAAAAAAAAAAAA", "AAAAAAAAAAAAAAAAAAAAAAAAAAA", "AAAAAAAAAAAAAAAAAAAAAAAAAAA", "AAAAAAAAAAAAAAAAAAAAAAAAAAA", "AAAAAAAAAAAAAAAAAAAAAAAAAAA", "AAAAAAAAAAAAAAAAAAAAAAAAAAA", "AAAAAAAAAAAAAAAAAAAAAAAAAAA", "AAAAAAAAAAAAAAAAAAAAAAAAAAA", "AAAAAAAAAAAAAAAAAAAAAAAAAAA", "AAAAAAAAAAAAAAAAAAAAAAAAAAA", "AAAAAAAAAAAAAAAAAAAAAAAAAAA", "AAAAAAAAAAAAAAAAAAAAAAAAAAA", "AAAAAAAAAAAAAAAAAAAAAAAAAAA", "AAAAAAAAAAAAAAAAAAAAAAAAAAA", "AAAAAAAAAAAAAAAAAAAAAAAAAAA", "AAAAAAAAAAAAAAAAAAAAAAAAAAA", "AAAAAAAAAAAAAAAAAAAAAAAAAAA", "AAAAAAAAAAAAAAAAAAAAAAAAAAA", "AAAAAAAAAAAAAAAAAAAAAAAAAAA")
            .aisle("BDDDDDDDDDDDDDDDDDDDDDDDDDB", "BDDDDDDDDDDDDDDDDDDDDDDDDDB", "AAAAAAAAAAFFFAAAAAAAAAAAAAA", "AAAAAAAAAAFFFAAAAAAAAAAAAAA", "AAAAAAAAAAFFFAAAAAAAAAAAAAA", "AAHIHAAAHHHHHHHAAAHIHAAAAAA", "AAHIHEEEHHHHHHHEEEHIHAAAAAA", "AAHIHAAAHHHHHHHAAAHIHAAAAAA", "AAAAAAAAAEFGFEAAAAAAAAAAAAA", "AAAAAAAAAEFGFEAAAAAAAAAAAAA", "AAAAAAAAAAAAAAAAAAAAAAAAAAA", "AAAAAAAAAAAAAAAAAAAAAAAAAAA", "AAAAAAAAAAAAAAAAAAAAAAAAAAA", "AAAAAAAAAAAAAAAAAAAAAAAAAAA", "AAAAAAAAAAAAAAAAAAAAAAAAAAA", "AAAAAAAAAAAAAAAAAAAAAAAAAAA", "AAAAAAAAAAAAAAAAAAAAAAAAAAA", "AAAAAAAAAAAAAAAAAAAAAAAAAAA", "AAAAAAAAAAAAAAAAAAAAAAAAAAA", "AAAAAAAAAAAAAAAAAAAAAAAAAAA", "AAAAAAAAAAAAAAAAAAAAAAAAAAA", "AAAAAAAAAAAAAAAAAAAAAAAAAAA", "AAAAAAAAAAAAAAAAAAAAAAAAAAA", "AAAAAAAAAAAAAAAAAAAAAAAAAAA", "AAAAAAAAAAAAAAAAAAAAAAAAAAA", "AAAAAAAAAAAAAAAAAAAAAAAAAAA")
            .aisle("BDDDDDDDDDDDDDDDDDDDDDDDDDB", "BDDDDDDDDDDDDDDDDDDDDDDDDDB", "AAAAAAAAAAFFFAAAAAAAAAAAAAA", "AAHIHAAAHHHHHHHAAAHIHAAAAAA", "AAHIHAAAHHHHHHHAAAHIHAAAAAA", "AAIFFJJJFFJJJFFJJJFFIAAAAAA", "AAIFFJJJFFJJJFFJJJFFIAAAAAA", "AAIFFJJJFFJJJFFJJJFFIAAAAAA", "AAHIHAAAHHHHHHHAAAHIHAAAAAA", "AAHIHAAAHHHHHHHAAAHIHAAAAAA", "AAAAAAAAAEFGFEAAAAAAAAAAAAA", "AAAAAAAAAAAAAAAAAAAAAAAAAAA", "AAAAAAAAAAAAAAAAAAAAAAAAAAA", "AAAAAAAAAAAAAAAAAAAAAAAAAAA", "AAAAAAAAAAAAAAAAAAAAAAAAAAA", "AAAAAAAAAAAAAAAAAAAAAAAAAAA", "AAAAAAAAAAAAAAAAAAAAAAAAAAA", "AAAAAAAAAAAAAAAAAAAAAAAAAAA", "AAAAAAAAAAAAAAAAAAAAAAAAAAA", "AAAAAAAAAAAAAAAAAAAAAAAAAAA", "AAAAAAAAAAAAAAAAAAAAAAAAAAA", "AAAAAAAAAAAAAAAAAAAAAAAAAAA", "AAAAAAAAAAAAAAAAAAAAAAAAAAA", "AAAAAAAAAAAAAAAAAAAAAAAAAAA", "AAAAAAAAAAAAAAAAAAAAAAAAAAA", "AAAAAAAAAAAAAAAAAAAAAAAAAAA")
            .aisle("BDDDDDDDDDDDDDDDDDDDDDDDDDB", "BDDDDDDDDDDDDDDDDDDDDDDDDDB", "AAAAAAAAAAFFFAAAAAAAAAAAAAA", "AAHIHAAAHHHHHHHAAAHIHAAAAAA", "AAIFFJJJFFJJJFFJJJFFIAAAAAA", "AAIAAAAAAAAAAAAAAAAAIAAAAAA", "AAAKEELEEEELEEEELEEKAAAAAAA", "AAIAAAAAAAAAAAAAAAAAIAAAAAA", "AAIFFJJJFFJJJFFJJJFFIAAAAAA", "AAHIHAAAHHHHHHHAAAHIHAAAAAA", "AAAAAAAAAEFGFEAAAAAAAAAAAAA", "AAAAAAAAAAAAAAAAAAAAAAAAAAA", "AAAAAAAAAAAAAAAAAAAAAAAAAAA", "AAAAAAAAAAAAAAAAAAAAAAAAAAA", "AAAAAAAAAAAAAAAAAAAAAAAAAAA", "AAAAAAAAAAAAAAAAAAAAAAAAAAA", "AAAAAAAAAAAAAAAAAAAAAAAAAAA", "AAAAAAAAAAAAAAAAAAAAAAAAAAA", "AAAAAAAAAAAAAAAAAAAAAAAAAAA", "AAAAAAAAAAAAAAAAAAAAAAAAAAA", "AAAAAAAAAAAAAAAAAAAAAAAAAAA", "AAAAAAAAAAAAAAAAAAAAAAAAAAA", "AAAAAAAAAAAAAAAAAAAAAAAAAAA", "AAAAAAAAAAAAAAAAAAAAAAAAAAA", "AAAAAAAAAAAAAAAAAAAAAAAAAAA", "AAAAAAAAAAAAAAAAAAAAAAAAAAA")
            .aisle("BDDDDDDDDDDDDDDDDDDDDDDDDDB", "BDDDDDDDDDDDDDDDDDDDDDDDDDB", "AAHIHAAAHHHHHHHAAAHIHAAGAAA", "AAIFFJJJFFJJJFFJJJFFIAAGAAA", "AAIAAAAAAAAAAAAAAAAAIAAGAAA", "AAIAAAAAAAAAAAAAAAAAIAAGAAA", "AAAKAALAAAALAAAALAAKGGGGAAA", "AAIAAAAAAAAAAAAAAAAAIAAAAAA", "AAIAAAAAAAAAAAAAAAAAIAAAAAA", "AAIFFJJJFFJJJFFJJJFFIAAAAAA", "AAHIHAAAHHHHHHHAAAHIHAAAAAA", "AAAAAAAAAEFGFEAAAAAAAAAAAAA", "AAAAAAAAAAAAAAAAAAAAAAAAAAA", "AAAAAAAAAAAAAAAAAAAAAAAAAAA", "AAAAAAAAAAAAAAAAAAAAAAAAAAA", "AAAAAAAAAAAAAAAAAAAAAAAAAAA", "AAAAAAAAAAAAAAAAAAAAAAAAAAA", "AAAAAAAAAAAAAAAAAAAAAAAAAAA", "AAAAAAAAAAAAAAAAAAAAAAAAAAA", "AAAAAAAAAAAAAAAAAAAAAAAAAAA", "AAAAAAAAAAAAAAAAAAAAAAAAAAA", "AAAAAAAAAAAAAAAAAAAAAAAAAAA", "AAAAAAAAAAAAAAAAAAAAAAAAAAA", "AAAAAAAAAAAAAAAAAAAAAAAAAAA", "AAAAAAAAAAAAAAAAAAAAAAAAAAA", "AAAAAAAAAAAAAAAAAAAAAAAAAAA")
            .aisle("BDDDDDDDDDDDDDDDDDDDDDDDDDB", "BDDDDDDDDDDDDDDDDDDDDDDDDDB", "AAHIHEEEHHHHHHHEEEHIHAGGGAA", "AAIFFJJJFFJJJFFJJJFFIAGGGAA", "AAAKEELEEEELEEEELEEKAAGGGAA", "AAAKAALAAAALAAAALAAKGGGGGAA", "AAAKLLLLLLLLLLLLLLLKGGGGGAA", "AAAKAALAAAALAAAALAAKGGGGAAA", "AAAKEELEEEELEEEELEEKAAAAAAA", "AAIFFJJJFFJJJFFJJJFFIAAAAAA", "AAHIHEEEHHHHHHHEEEHIHAAAAAA", "AAAAAAAAAEFGFEAAAAAAAAAAAAA", "AAAAAAAAAAAAAAAAAAAAAAAAAAA", "AAAAAAAAAAAAAAAAAAAAAAAAAAA", "AAAAAAAAAAAAAAAAAAAAAAAAAAA", "AAAAAAAAAAAAAAAAAAAAAAAAAAA", "AAAAAAAAAAAAAAAAAAAAAAAAAAA", "AAAAAAAAAAAAAAAAAAAAAAAAAAA", "AAAAAAAAAAAAAAAAAAAAAAAAAAA", "AAAAAAAAAAAAAAAAAAAAAAAAAAA", "AAAAAAAAAAAAAAAAAAAAAAAAAAA", "AAAAAAAAAAAAAAAAAAAAAAAAAAA", "AAAAAAAAAAAAAAAAAAAAAAAAAAA", "AAAAAAAAAAAAAAAAAAAAAAAAAAA", "AAAAAAAAAAAAAAAAAAAAAAAAAAA", "AAAAAAAAAAAAAAAAAAAAAAAAAAA")
            .aisle("BDDDDDDDDDDDDDDDDDDDDDDDDDB", "BDDDDDDDDDDDDDDDDDDDDDDDDDB", "AAHIHAAAHHHHHHHAAAHIHAAGAAA", "AAIFFJJJFFJJJFFJJJFFIAAGAAA", "AAIAAAAAAAAAAAAAAAAAIAAGAAA", "AAIAAAAAAAAAAAAAAAAAIAAGAAA", "AAAKAALAAAALAAAALAAKGGGGAAA", "AAIAAAAAAAAAAAAAAAAAIAAAAAA", "AAIAAAAAAAAAAAAAAAAAIAAAAAA", "AAIFFJJJFFJJJFFJJJFFIAAAAAA", "AAHIHAAAHHHHHHHAAAHIHAAAAAA", "AAAAAAAAAEFGFEAAAAAAAAAAAAA", "AAAAAAAAAAAAAAAAAAAAAAAAAAA", "AAAAAAAAAAAAAAAAAAAAAAAAAAA", "AAAAAAAAAAAAAAAAAAAAAAAAAAA", "AAAAAAAAAAAAAAAAAAAAAAAAAAA", "AAAAAAAAAAAAAAAAAAAAAAAAAAA", "AAAAAAAAAAAAAAAAAAAAAAAAAAA", "AAAAAAAAAAAAAAAAAAAAAAAAAAA", "AAAAAAAAAAAAAAAAAAAAAAAAAAA", "AAAAAAAAAAAAAAAAAAAAAAAAAAA", "AAAAAAAAAAAAAAAAAAAAAAAAAAA", "AAAAAAAAAAAAAAAAAAAAAAAAAAA", "AAAAAAAAAAAAAAAAAAAAAAAAAAA", "AAAAAAAAAAAAAAAAAAAAAAAAAAA", "AAAAAAAAAAAAAAAAAAAAAAAAAAA")
            .aisle("BDDDDDDDDDDDDDDDDDDDDDDDDDB", "BDDDDDDDDDDDDDDDDDDDDDDDDDB", "AAAAAAAAAAFFFAAAAAAAAAAAAAA", "AAHIHAAAHHHHHHHAAAHIHAAAAAA", "AAIFFJJJFFJJJFFJJJFFIAAAAAA", "AAIAAAAAAAAAAAAAAAAAIAAAAAA", "AAAKEELEEEELEEEELEEKAAAAAAA", "AAIAAAAAAAAAAAAAAAAAIAAAAAA", "AAIFFJJJFFJJJFFJJJFFIAAAAAA", "AAHIHAAAHHHHHHHAAAHIHAAAAAA", "AAAAAAAAAEFGFEAAAAAAAAAAAAA", "AAAAAAAAAAAAAAAAAAAAAAAAAAA", "AAAAAAAAAAAAAAAAAAAAAAAAAAA", "AAAAAAAAAAAAAAAAAAAAAAAAAAA", "AAAAAAAAAAAAAAAAAAAAAAAAAAA", "AAAAAAAAAAAAAAAAAAAAAAAAAAA", "AAAAAAAAAAAAAAAAAAAAAAAAAAA", "AAAAAAAAAAAAAAAAAAAAAAAAAAA", "AAAAAAAAAAAAAAAAAAAAAAAAAAA", "AAAAAAAAAAAAAAAAAAAAAAAAAAA", "AAAAAAAAAAAAAAAAAAAAAAAAAAA", "AAAAAAAAAAAAAAAAAAAAAAAAAAA", "AAAAAAAAAAAAAAAAAAAAAAAAAAA", "AAAAAAAAAAAAAAAAAAAAAAAAAAA", "AAAAAAAAAAAAAAAAAAAAAAAAAAA", "AAAAAAAAAAAAAAAAAAAAAAAAAAA")
            .aisle("BDDDDDDDDDDDDDDDDDDDDDDDDDB", "BDDDDDDDDDDDDDDDDDDDDDDDDDB", "AAAAAAAAAAFFFAAAAAAAAAAAAAA", "AAHIHAAAHHHHHHHAAAHIHAAAAAA", "AAHIHAAAHHHHHHHAAAHIHAAAAAA", "AAIFFJJJFFJJJFFJJJFFIAAAAAA", "AAIFFJJJFFJJJFFJJJFFIAAAAAA", "AAIFFJJJFFJJJFFJJJFFIAAAAAA", "AAHIHAAAHHHHHHHAAAHIHAAAAAA", "AAHIHAAAHHHHHHHAAAHIHAAAAAA", "AAAAAAAAAEFGFEAAAAAAAAAAAAA", "AAAAAAAAAAAAAAAAAAAAAAAAAAA", "AAAAAAAAAAAAAAAAAAAAAAAAAAA", "AAAAAAAAAAAAAAAAAAAAAAAAAAA", "AAAAAAAAAAAAAAAAAAAAAAAAAAA", "AAAAAAAAAAAAAAAAAAAAAAAAAAA", "AAAAAAAAAAAAAAAAAAAAAAAAAAA", "AAAAAAAAAAAAAAAAAAAAAAAAAAA", "AAAAAAAAAAAAAAAAAAAAAAAAAAA", "AAAAAAAAAAAAAAAAAAAAAAAAAAA", "AAAAAAAAAAAAAAAAAAAAAAAAAAA", "AAAAAAAAAAAAAAAAAAAAAAAAAAA", "AAAAAAAAAAAAAAAAAAAAAAAAAAA", "AAAAAAAAAAAAAAAAAAAAAAAAAAA", "AAAAAAAAAAAAAAAAAAAAAAAAAAA", "AAAAAAAAAAAAAAAAAAAAAAAAAAA")
            .aisle("BDDDDDDDDDDDDDDDDDDDDDDDDDB", "BDDDDDDDDDDDDDDDDDDDDDDDDDB", "AAAAAAAAAAFFFAAAAAAAAAAAAAA", "AAAAAAAAAAFFFAAAAAAAAAAAAAA", "AAAAAAAAAAFFFAAAAAAAAAAAAAA", "AAHIHAAAHHHHHHHAAAHIHAAAAAA", "AAHIHEEEHHHHHHHEEEHIHAAAAAA", "AAHIHAAAHHHHHHHAAAHIHAAAAAA", "AAAAAAAAAEFGFEAAAAAAAAAAAAA", "AAAAAAAAAEFGFEAAAAAAAAAAAAA", "AAAAAAAAAAAAAAAAAAAAAAAAAAA", "AAAAAAAAAAAAAAAAAAAAAAAAAAA", "AAAAAAAAAAAAAAAAAAAAAAAAAAA", "AAAAAAAAAAAAAAAAAAAAAAAAAAA", "AAAAAAAAAAAAAAAAAAAAAAAAAAA", "AAAAAAAAAAAAAAAAAAAAAAAAAAA", "AAAAAAAAAAAAAAAAAAAAAAAAAAA", "AAAAAAAAAAAAAAAAAAAAAAAAAAA", "AAAAAAAAAAAAAAAAAAAAAAAAAAA", "AAAAAAAAAAAAAAAAAAAAAAAAAAA", "AAAAAAAAAAAAAAAAAAAAAAAAAAA", "AAAAAAAAAAAAAAAAAAAAAAAAAAA", "AAAAAAAAAAAAAAAAAAAAAAAAAAA", "AAAAAAAAAAAAAAAAAAAAAAAAAAA", "AAAAAAAAAAAAAAAAAAAAAAAAAAA", "AAAAAAAAAAAAAAAAAAAAAAAAAAA")
            .aisle("BDDDDDDDDDDDDDDDDDDDDDDDDDB", "BDDDDDDDDDDDDDDDDDDDDDDDDDB", "AAAAAAAAAEFGFEAAAAAAAAAAAAA", "AAAAAAAAAEFGFEAAAAAAAAAAAAA", "AAAAAAAAAEFGFEAAAAAAAAAAAAA", "AAAAAAAAAEFGFEAAAAAAAAAAAAA", "AAAAAAAAAEFGFEAAAAAAAAAAAAA", "AAAAAAAAAEFGFEAAAAAAAAAAAAA", "AAAAAAAAAAAAAAAAAAAAAAAAAAA", "AAAAAAAAAAAAAAAAAAAAAAAAAAA", "AAAAAAAAAAAAAAAAAAAAAAAAAAA", "AAAAAAAAAAAAAAAAAAAAAAAAAAA", "AAAAAAAAAAAAAAAAAAAAAAAAAAA", "AAAAAAAAAAAAAAAAAAAAAAAAAAA", "AAAAAAAAAAAAAAAAAAAAAAAAAAA", "AAAAAAAAAAAAAAAAAAAAAAAAAAA", "AAAAAAAAAAAAAAAAAAAAAAAAAAA", "AAAAAAAAAAAAAAAAAAAAAAAAAAA", "AAAAAAAAAAAAAAAAAAAAAAAAAAA", "AAAAAAAAAAAAAAAAAAAAAAAAAAA", "AAAAAAAAAAAAAAAAAAAAAAAAAAA", "AAAAAAAAAAAAAAAAAAAAAAAAAAA", "AAAAAAAAAAAAAAAAAAAAAAAAAAA", "AAAAAAAAAAAAAAAAAAAAAAAAAAA", "AAAAAAAAAAAAAAAAAAAAAAAAAAA", "AAAAAAAAAAAAAAAAAAAAAAAAAAA")
            .aisle("BDDDDDDDDDDDDDDDDDDDDDDDDDB", "BDDDDDDDDDDDDDDDDDDDDDDDDDB", "AAAAAAMAAANNNAAAMAAAAAAAAAA", "AAAAAAMAAAANAAAAMAAAAAAAAAA", "AAAAMMMMMAAAAAMMMMMAAAAAAAA", "AAAAAAMAAAAAAAAAMAAAAAAAAAA", "AAAAAAMAAAAAAAAAMAAAAAAAAAA", "AAAAAAMAAAAAAAAAMAAAAAAAAAA", "AAAAAAAAAAAAAAAAAAAAAAAAAAA", "AAAAAAAAAAAAAAAAAAAAAAAAAAA", "AAAAAAAAAAAAAAAAAAAAAAAAAAA", "AAAAAAAAAAAAAAAAAAAAAAAAAAA", "AAAAAAAAAAAAAAAAAAAAAAAAAAA", "AAAAAAAAAAAAAAAAAAAAAAAAAAA", "AAAAAAAAAAAAAAAAAAAAAAAAAAA", "AAAAAAAAAAAAAAAAAAAAAAAAAAA", "AAAAAAAAAAAAAAAAAAAAAAAAAAA", "AAAAAAAAAAAAAAAAAAAAAAAAAAA", "AAAAAAAAAAAAAAAAAAAAAAAAAAA", "AAAAAAAAAAAAAAAAAAAAAAAAAAA", "AAAAAAAAAAAAAAAAAAAAAAAAAAA", "AAAAAAAAAAAAAAAAAAAAAAAAAAA", "AAAAAAAAAAAAAAAAAAAAAAAAAAA", "AAAAAAAAAAAAAAAAAAAAAAAAAAA", "AAAAAAAAAAAAAAAAAAAAAAAAAAA", "AAAAAAAAAAAAAAAAAAAAAAAAAAA")
            .aisle("BDDDDDDDDDDDDDDDDDDDDDDDDDB", "BDDDDDDDDDDDDDDDDDDDDDDDDDB", "AAAAOOOOOANNNAOOOOOAAAAAAAA", "AAAAOOOOOAANAAOOOOOAAAAAAAA", "AAAMOOOOOMAAAMOOOOOMAAAAAAA", "AAAAOOOOOAAAAAOOOOOAAAAAAAA", "AAAAOOOOOAAAAAOOOOOAAAAAAAA", "AAAAAAMAAAAAAAAAMAAAAAAAAAA", "AAAAAAAAAAAAAAAAAAAAAAAAAAA", "AAAAAAAAAAAAAAAAAAAAAAAAAAA", "AAAAAAAAAAAAAAAAAAAAAAAAAAA", "AAAAAAAAAAAAAAAAAAAAAAAAAAA", "AAAAAAAAAAAAAAAAAAAAAAAAAAA", "AAAAAAAAAAAAAAAAAAAAAAAAAAA", "AAAAAAAAAAAAAAAAAAAAAAAAAAA", "AAAAAAAAAAAAAAAAAAAAAAAAAAA", "AAAAAAAAAAAAAAAAAAAAAAAAAAA", "AAAAAAAAAAAAAAAAAAAAAAAAAAA", "AAAAAAAAAAAAAAAAAAAAAAAAAAA", "AAAAAAAAAAAAAAAAAAAAAAAAAAA", "AAAAAAAAAAAAAAAAAAAAAAAAAAA", "AAAAAAAAAAAAAAAAAAAAAAAAAAA", "AAAAAAAAAAAAAAAAAAAAAAAAAAA", "AAAAAAAAAAAAAAAAAAAAAAAAAAA", "AAAAAAAAAAAAAAAAAAAAAAAAAAA", "AAAAAAAAAAAAAAAAAAAAAAAAAAA")
            .aisle("BDDDDDDDDDDDDDDDDDDDDDDDDDB", "BDDDDDDDDDDDDDDDDDDDDDDDDDB", "AAAOOOOOOONNNOOOOOOOAAAAAAA", "AAAOAAAAAOANAOAAAAAOAAAAAAA", "AAMOAAAAAOMAMOAAAAAOMAAAAAA", "AAAOAAAAAOAAAOAAAAAOAAAAAAA", "AAAOOOOOOOAAAOOOOOOOAAAAAAA", "AAAAAAMAAAAAAAAAMAAAAAAAAAA", "AAAAAAAAAAAAAAAAAAAAAAAAAAA", "AAAAAAAAAAAAAAAAAAAAAAAAAAA", "AAAAAAAAAAAAAAAAAAAAAAAAAAA", "AAAAAAAAAAAAAAAAAAAAAAAAAAA", "AAAAAAAAAAAAAAAAAAAAAAAAAAA", "AAAAAAAAAAAAAAAAAAAAAAAAAAA", "AAAAAAAAAAAAAAAAAAAAAAAAAAA", "AAAAAAAAAAAAAAAAAAAAAAAAAAA", "AAAAAAAAAAAAAAAAAAAAAAAAAAA", "AAAAAAAAAAAAAAAAAAAAAAAAAAA", "AAAAAAAAAAAAAAAAAAAAAAAAAAA", "AAAAAAAAAAAAAAAAAAAAAAAAAAA", "AAAAAAAAAAAAAAAAAAAAAAAAAAA", "AAAAAAAAAAAAAAAAAAAAAAAAAAA", "AAAAAAAAAAAAAAAAAAAAAAAAAAA", "AAAAAAAAAAAAAAAAAAAAAAAAAAA", "AAAAAAAAAAAAAAAAAAAAAAAAAAA", "AAAAAAAAAAAAAAAAAAAAAAAAAAA")
            .aisle("BDDDDDDDDDDDDDDDDDDDDDDDDDB", "BDDDDDDDDDDDDDDDDDDDDDDDDDB", "AAOOOOOOOOONOOOOOOOOOAEPEAA", "AAOAAAAAAAONOAAAAAAAOAEPEAA", "AMOAAAAAAAOMOAAAAAAAOMEPEAA", "AAOAAAAAAAOAOAAAAAAAOAAAAAA", "AAOOOOOOOOOAOOOOOOOOOAAAAAA", "AAAAAAMAAAAAAAAAMAAAAAAAAAA", "AAAAAAAAAAAAAAAAAAAAAAAAAAA", "AAAAAAAAAAAAAAAAAAAAAAAAAAA", "AAAAAAAAAAAAAAAAAAAAAAAAAAA", "AAAAAAAAAAAAAAAAAAAAAAAAAAA", "AAAAAAAAAAAAAAAAAAAAAAAAAAA", "AAAAAAAAAAAAAAAAAAAAAAAAAAA", "AAAAAAAAAAAAAAAAAAAAAAAAAAA", "AAAAAAAAAAAAAAAAAAAAAAAAAAA", "AAAAAAAAAAAAAAAAAAAAAAAAAAA", "AAAAAAAAAAAAAAAAAAAAAAAAAAA", "AAAAAAAAAAAAAAAAAAAAAAAAAAA", "AAAAAAAAAAAAAAAAAAAAAAAAAAA", "AAAAAAAAAAAAAAAAAAAAAAAAAAA", "AAAAAAAAAAAAAAAAAAAAAAAAAAA", "AAAAAAAAAAAAAAAAAAAAAAAAAAA", "AAAAAAAAAAAAAAAAAAAAAAAAAAA", "AAAAAAAAAAAAAAAAAAAAAAAAAAA", "AAAAAAAAAAAAAAAAAAAAAAAAAAA")
            .aisle("BDDDDDDDDDDDDDDDDDDDDDDDDDB", "BDDDDDDDDDDDDDDDDDDDDDDDDDB", "AAOOOOOOOOONOOOOOOOOOAPPPAA", "AAOAAAAAAAONOAAAAAAAOAPPPAA", "AMOAAAAAAAOMOAAAAAAAOMEPEAA", "AAOAAAAAAAOAOAAAAAAAOAAAAAA", "AAOOOOOOOOOAOOOOOOOOOAAAAAA", "AAAAAAMAAAAAAAAAMAAAAAAAAAA", "AAAAAAAAAAAAAAAAAAAAAAAAAAA", "AAAAAAAAAAAAAAAAAAAAAAAAAAA", "AAAAAAAAAAAAAAAAAAAAAAAAAAA", "AAAAAAAAAAAAAAAAAAAAAAAAAAA", "AAAAAAAAAAAAAAAAAAAAAAAAAAA", "AAAAAAAAAAAAAAAAAAAAAAAAAAA", "AAAAAAAAAAAAAAAAAAAAAAAAAAA", "AAAAAAAAAAAAAAAAAAAAAAAAAAA", "AAAAAAAAAAAAAAAAAAAAAAAAAAA", "AAAAAAAAAAAAAAAAAAAAAAAAAAA", "AAAAAAAAAAAAAAAAAAAAAAAAAAA", "AAAAAAAAAAAAAAAAAAAAAAAAAAA", "AAAAAAAAAAAAAAAAAAAAAAAAAAA", "AAAAAAAAAAAAAAAAAAAAAAAAAAA", "AAAAAAAAAAAAAAAAAAAAAAAAAAA", "AAAAAAAAAAAAAAAAAAAAAAAAAAA", "AAAAAAAAAAAAAAAAAAAAAAAAAAA", "AAAAAAAAAAAAAAAAAAAAAAAAAAA")
            .aisle("BDDDDDDDDDDDDDDDDDDDDDDDDDB", "BDDDDDDDDDDDDDDDDDDDDDDDDDB", "AMOOOOOOOOOMOOOOOOOOOMPPPAA", "AMOAAAMAAAOMOAAAMAAAOMPPPAA", "AMOAAAMAAAOMOAAAMAAAOMEPEAA", "AMOAAAMAAAOMOAAAMAAAOMAAAAA", "AMOOOOMOOOOMOOOOMOOOOMAAAAA", "AMMMMMMMMMMMMMMMMMMMMMAAAAA", "AAAAAAAAAAAAAAAAAAAAAAAAAAA", "AAAAAAAAAAAAAAAAAAAAAAAAAAA", "AAAAAAAAAAAAAAAAAAAAAAAAAAA", "AAAAAAAAAAAAAAAAAAAAAAAAAAA", "AAAAAAAAAAAAAAAAAAAAAAAAAAA", "AAAAAAAAAAAAAAAAAAAAAAAAAAA", "AAAAAAAAAAAAAAAAAAAAAAAAAAA", "AAAAAAAAAAAAAAAAAAAAAAAAAAA", "AAAAAAAAAAAAAAAAAAAAAAAAAAA", "AAAAAAAAAAAAAAAAAAAAAAAAAAA", "AAAAAAAAAAAAAAAAAAAAAAAAAAA", "AAAAAAAAAAAAAAAAAAAAAAAAAAA", "AAAAAAAAAAAAAAAAAAAAAAAAAAA", "AAAAAAAAAAAAAAAAAAAAAAAAAAA", "AAAAAAAAAAAAAAAAAAAAAAAAAAA", "AAAAAAAAAAAAAAAAAAAAAAAAAAA", "AAAAAAAAAAAAAAAAAAAAAAAAAAA", "AAAAAAAAAAAAAAAAAAAAAAAAAAA")
            .aisle("BDDDDDDDDDDDDDDDDDDDDDDDDDB", "BDDDDDDDDDDDDDDDDDDDDDDDDDB", "AAOOOOOOOOOAOOOOOOOOOAPPPAA", "AAOAAAAAAAOAOAAAAAAAOAPPPAA", "AMOAAAAAAAOMOAAAAAAAOMEPEAA", "AAOAAAAAAAOAOAAAAAAAOAAAAAA", "AAOOOOOOOOOAOOOOOOOOOAAAAAA", "AAAAAAMAAAAAAAAAMAAAAAAAAAA", "AAAAAAAAAAAAAAAAAAAAAAAAAAA", "AAAAAAAAAAAAAAAAAAAAAAAAAAA", "AAAAAAAAAAAAAAAAAAAAAAAAAAA", "AAAAAAAAAAAAAAAAAAAAAAAAAAA", "AAAAAAAAAAAAAAAAAAAAAAAAAAA", "AAAAAAAAAAAAAAAAAAAAAAAAAAA", "AAAAAAAAAAAAAAAAAAAAAAAAAAA", "AAAAAAAAAAAAAAAAAAAAAAAAAAA", "AAAAAAAAAAAAAAAAAAAAAAAAAAA", "AAAAAAAAAAAAAAAAAAAAAAAAAAA", "AAAAAAAAAAAAAAAAAAAAAAAAAAA", "AAAAAAAAAAAAAAAAAAAAAAAAAAA", "AAAAAAAAAAAAAAAAAAAAAAAAAAA", "AAAAAAAAAAAAAAAAAAAAAAAAAAA", "AAAAAAAAAAAAAAAAAAAAAAAAAAA", "AAAAAAAAAAAAAAAAAAAAAAAAAAA", "AAAAAAAAAAAAAAAAAAAAAAAAAAA", "AAAAAAAAAAAAAAAAAAAAAAAAAAA")
            .aisle("BDDDDDDDDDDDDDDDDDDDDDDDDDB", "BDDDDDDDDDDDDDDDDDDDDDDDDDB", "AAOOOOOOOOOAOOOOOOOOOAPPPAA", "AAOAAAAAAAOAOAAAAAAAOAPPPAA", "AMOAAAAAAAOMOAAAAAAAOMEPEAA", "AAOAAAAAAAOAOAAAAAAAOAAAAAA", "AAOOOOOOOOOAOOOOOOOOOAAAAAA", "AAAAAAMAAAAAAAAAMAAAAAAAAAA", "AAAAAAAAAAAAAAAAAAAAAAAAAAA", "AAAAAAAAAAAAAAAAAAAAAAAAAAA", "AAAAAAAAAAAAAAAAAAAAAAAAAAA", "AAAAAAAAAAAAAAAAAAAAAAAAAAA", "AAAAAAAAAAAAAAAAAAAAAAAAAAA", "AAAAAAAAAAAAAAAAAAAAAAAAAAA", "AAAAAAAAAAAAAAAAAAAAAAAAAAA", "AAAAAAAAAAAAAAAAAAAAAAAAAAA", "AAAAAAAAAAAAAAAAAAAAAAAAAAA", "AAAAAAAAAAAAAAAAAAAAAAAAAAA", "AAAAAAAAAAAAAAAAAAAAAAAAAAA", "AAAAAAAAAAAAAAAAAAAAAAAAAAA", "AAAAAAAAAAAAAAAAAAAAAAAAAAA", "AAAAAAAAAAAAAAAAAAAAAAAAAAA", "AAAAAAAAAAAAAAAAAAAAAAAAAAA", "AAAAAAAAAAAAAAAAAAAAAAAAAAA", "AAAAAAAAAAAAAAAAAAAAAAAAAAA", "AAAAAAAAAAAAAAAAAAAAAAAAAAA")
            .aisle("BDDDDDDDDDDDDDDDDDDDDDDDDDB", "BDDDDDDDDDDDDDDDDDDDDDDDDDB", "AAAOOOOOOOAAAOOOOOOOAAPPPAA", "AAAOAAAAAOAAAOAAAAAOAAPPPAA", "AAMOAAAAAOMAMOAAAAAOMAEPEAA", "AAAOAAAAAOAAAOAAAAAOAAAAAAA", "AAAOOOOOOOAAAOOOOOOOAAAAAAA", "AAAAAAMAAAAAAAAAMAAAAAAAAAA", "AAAAAAAAAAAAAAAAAAAAAAAAAAA", "AAAAAAAAAAAAAAAAAAAAAAAAAAA", "AAAAAAAAAAAAAAAAAAAAAAAAAAA", "AAAAAAAAAAAAAAAAAAAAAAAAAAA", "AAAAAAAAAAAAAAAAAAAAAAAAAAA", "AAAAAAAAAAAAAAAAAAAAAAAAAAA", "AAAAAAAAAAAAAAAAAAAAAAAAAAA", "AAAAAAAAAAAAAAAAAAAAAAAAAAA", "AAAAAAAAAAAAAAAAAAAAAAAAAAA", "AAAAAAAAAAAAAAAAAAAAAAAAAAA", "AAAAAAAAAAAAAAAAAAAAAAAAAAA", "AAAAAAAAAAAAAAAAAAAAAAAAAAA", "AAAAAAAAAAAAAAAAAAAAAAAAAAA", "AAAAAAAAAAAAAAAAAAAAAAAAAAA", "AAAAAAAAAAAAAAAAAAAAAAAAAAA", "AAAAAAAAAAAAAAAAAAAAAAAAAAA", "AAAAAAAAAAAAAAAAAAAAAAAAAAA", "AAAAAAAAAAAAAAAAAAAAAAAAAAA")
            .aisle("BDDDDDDDDDDDDDDDDDDDDDDDDDB", "BDDDDDDDDDDDDDDDDDDDDDDDDDB", "AAAAOOOOOAAAAAOOOOOAAAPPPAA", "AAAAOOOOOAAAAAOOOOOAAAPPPAA", "AAAMOOOOOMAAAMOOOOOMAAEPEAA", "AAAAOOOOOAAAAAOOOOOAAAAAAAA", "AAAAOOOOOAAAAAOOOOOAAAAAAAA", "AAAAAAMAAAAAAAAAMAAAAAAAAAA", "AAAAAAAAAAAAAAAAAAAAAAAAAAA", "AAAAAAAAAAAAAAAAAAAAAAAAAAA", "AAAAAAAAAAAAAAAAAAAAAAAAAAA", "AAAAAAAAAAAAAAAAAAAAAAAAAAA", "AAAAAAAAAAAAAAAAAAAAAAAAAAA", "AAAAAAAAAAAAAAAAAAAAAAAAAAA", "AAAAAAAAAAAAAAAAAAAAAAAAAAA", "AAAAAAAAAAAAAAAAAAAAAAAAAAA", "AAAAAAAAAAAAAAAAAAAAAAAAAAA", "AAAAAAAAAAAAAAAAAAAAAAAAAAA", "AAAAAAAAAAAAAAAAAAAAAAAAAAA", "AAAAAAAAAAAAAAAAAAAAAAAAAAA", "AAAAAAAAAAAAAAAAAAAAAAAAAAA", "AAAAAAAAAAAAAAAAAAAAAAAAAAA", "AAAAAAAAAAAAAAAAAAAAAAAAAAA", "AAAAAAAAAAAAAAAAAAAAAAAAAAA", "AAAAAAAAAAAAAAAAAAAAAAAAAAA", "AAAAAAAAAAAAAAAAAAAAAAAAAAA")
            .aisle("BDDDDDDDDDDDDDDDDDDDDDDDDDB", "BDDDDDDDDDDDDDDDDDDDDDDDDDB", "AAAAAAMAAAAAAAAAMAAAAAPPPAA", "AAAAAAMAAAAAAAAAMAAAAAPPPAA", "AAAAMMMMMAAAAAMMMMMAAAEPEAA", "AAAAAAMAAAAAAAAAMAAAAAAAAAA", "AAAAAAMAAAAAAAAAMAAAAAAAAAA", "AAAAAAMAAAAAAAAAMAAAAAAAAAA", "AAAAAAAAAAAAAAAAAAAAAAAAAAA", "AAAAAAAAAAAAAAAAAAAAAAAAAAA", "AAAAAAAAAAAAAAAAAAAAAAAAAAA", "AAAAAAAAAAAAAAAAAAAAAAAAAAA", "AAAAAAAAAAAAAAAAAAAAAAAAAAA", "AAAAAAAAAAAAAAAAAAAAAAAAAAA", "AAAAAAAAAAAAAAAAAAAAAAAAAAA", "AAAAAAAAAAAAAAAAAAAAAAAAAAA", "AAAAAAAAAAAAAAAAAAAAAAAAAAA", "AAAAAAAAAAAAAAAAAAAAAAAAAAA", "AAAAAAAAAAAAAAAAAAAAAAAAAAA", "AAAAAAAAAAAAAAAAAAAAAAAAAAA", "AAAAAAAAAAAAAAAAAAAAAAAAAAA", "AAAAAAAAAAAAAAAAAAAAAAAAAAA", "AAAAAAAAAAAAAAAAAAAAAAAAAAA", "AAAAAAAAAAAAAAAAAAAAAAAAAAA", "AAAAAAAAAAAAAAAAAAAAAAAAAAA", "AAAAAAAAAAAAAAAAAAAAAAAAAAA")
            .aisle("BDDDDDDDDDDDDDDDDDDDDDDDDDB", "BDDDDDDDDDDDDDDDDDDDDDDDDDB", "AAEPPEAAAEPPEAAAAAAAAAPPPAA", "AAEQQEAAAEQQEAAAAAAAAAPPPAA", "AAEGGEAAAEGGEAAAAAAAAAEPEAA", "AARHHRAAARHHRAAAAAAAAAAAAAA", "AARHHRAAARHHRAAAAAAAAAAAAAA", "AARHHRAAARHHRAAAAAAAAAAAAAA", "AARHHRAAARHHRAAAAAAAAAAAAAA", "AARHHRAAARHHRAAAAAAAAAAAAAA", "AARHHRAAARHHRAAAAAAAAAAAAAA", "AAEGGEAAAEGGEAAAAAAAAAAAAAA", "AARHHRAAARHHRAAAAAAAAAAAAAA", "AARHHRAAARHHRAAAAAAAAAAAAAA", "AARHHRAAARHHRAAAAAAAAAAAAAA", "AARHHRAAARHHRAAAAAAAAAAAAAA", "AARHHRAAARHHRAAAAAAAAAAAAAA", "AAEGGEAAAEGGEAAAAAAAAAAAAAA", "AARHHRAAARHHRAAAAAAAAAAAAAA", "AARHHRAAARHHRAAAAAAAAAAAAAA", "AARHHRAAARHHRAAAAAAAAAAAAAA", "AARHHRAAARHHRAAAAAAAAAAAAAA", "AARHHRAAARHHRAAAAAAAAAAAAAA", "AARHHRAAARHHRAAAAAAAAAAAAAA", "AAEGGEAAAEGGEAAAAAAAAAAAAAA", "AAEAAEAAAEAAEAAAAAAAAAAAAAA")
            .aisle("BDDDDDDDDDDDDDDDDDDDDDDDDDB", "BDDDDDDDDDDDDDDDDDDDDDDDDDB", "AEPPPPEAEPPPPEAAAAAAAAPPPAA", "AEQQQQEAEQQQQEAAAAAAAAPPPAA", "AEGGGGEAEGGGGEAAAAAAAAEPEAA", "ARHBBHRARHBBHRAAAAAAAAAAAAA", "ARHBBHRARHBBHRAAAAAAAAAAAAA", "ARHBBHRARHBBHRAAAAAAAAAAAAA", "ARHBBHRARHBBHRAAAAAAAAAAAAA", "ARHBBHRARHBBHRAAAAAAAAAAAAA", "ARHBBHRARHBBHRAAAAAAAAAAAAA", "AEGBBGEAEGBBGEAAAAAAAAAAAAA", "ARHBBHRARHBBHRAAAAAAAAAAAAA", "ARHBBHRARHBBHRAAAAAAAAAAAAA", "ARHBBHRARHBBHRAAAAAAAAAAAAA", "ARHBBHRARHBBHRAAAAAAAAAAAAA", "ARHBBHRARHBBHRAAAAAAAAAAAAA", "AEGBBGEAEGBBGEAAAAAAAAAAAAA", "ARHBBHRARHBBHRAAAAAAAAAAAAA", "ARHBBHRARHBBHRAAAAAAAAAAAAA", "ARHBBHRARHBBHRAAAAAAAAAAAAA", "ARHBBHRARHBBHRAAAAAAAAAAAAA", "ARHBBHRARHBBHRAAAAAAAAAAAAA", "ARHBBHRARHBBHRAAAAAAAAAAAAA", "AEGGGGEAEGGGGEAAAAAAAAAAAAA", "AEEEEEEAEEEEEEAAAAAAAAAAAAA")
            .aisle("BDDDDDDDDDDDDDDDDDDDDDDDDDB", "BDDDDDDDDDDDDDDDDDDDDDDDDDB", "APPPPPPAPPPPPPAAAAAAAAEPEAA", "AQQQQQQAQQQQQQAAAAAAAAEPEAA", "AGGGGGGAGGGGGGAAAAAAAAEPEAA", "AHBLQBHAHBLQBHAAAAAAAAAAAAA", "AHBLQBHAHBLQBHAAAAAAAAAAAAA", "AHBLQBHAHBLQBHAAAAAAAAAAAAA", "AHBLQBHAHBLQBHAAAAAAAAAAAAA", "AHBLQBHAHBLQBHAAAAAAAAAAAAA", "AHBLQBHAHBLQBHAAAAAAAAAAAAA", "AGBLQBGAGBLQBGAAAAAAAAAAAAA", "AHBLQBHAHBLQBHAAAAAAAAAAAAA", "AHBLQBHAHBLQBHAAAAAAAAAAAAA", "AHBLQBHAHBLQBHAAAAAAAAAAAAA", "AHBLQBHAHBLQBHAAAAAAAAAAAAA", "AHBLQBHAHBLQBHAAAAAAAAAAAAA", "AGBLQBGAGBLQBGAAAAAAAAAAAAA", "AHBLQBHAHBLQBHAAAAAAAAAAAAA", "AHBLQBHAHBLQBHAAAAAAAAAAAAA", "AHBLQBHAHBLQBHAAAAAAAAAAAAA", "AHBLQBHAHBLQBHAAAAAAAAAAAAA", "AHBLQBHAHBLQBHAAAAAAAAAAAAA", "AHBLQBHAHBLQBHAAAAAAAAAAAAA", "AGGGGGGAGGGGGGAAAAAAAAAAAAA", "AAAAAAEAEAAAAAAAAAAAAAAAAAA")
            .aisle("BDDDDDDDDDDDDDDDDDDDDDDDDDB", "BDDDDDDDDDDDDDDDDDDDDDDDDDB", "APPPPPPAPPPPPPAAAAAAAAASAAA", "AQQQQQQAQQQQQQAAAAAAAAATAAA", "AGGGGGGAGGGGGGAAAAAAAAAAAAA", "AHBQLBHAHBQLBHAAAAAAAAAAAAA", "AHBQLBHAHBQLBHAAAAAAAAAAAAA", "AHBQLBHAHBQLBHAAAAAAAAAAAAA", "AHBQLBHAHBQLBHAAAAAAAAAAAAA", "AHBQLBHAHBQLBHAAAAAAAAAAAAA", "AHBQLBHAHBQLBHAAAAAAAAAAAAA", "AGBQLBGAGBQLBGAAAAAAAAAAAAA", "AHBQLBHAHBQLBHAAAAAAAAAAAAA", "AHBQLBHAHBQLBHAAAAAAAAAAAAA", "AHBQLBHAHBQLBHAAAAAAAAAAAAA", "AHBQLBHAHBQLBHAAAAAAAAAAAAA", "AHBQLBHAHBQLBHAAAAAAAAAAAAA", "AGBQLBGAGBQLBGAAAAAAAAAAAAA", "AHBQLBHAHBQLBHAAAAAAAAAAAAA", "AHBQLBHAHBQLBHAAAAAAAAAAAAA", "AHBQLBHAHBQLBHAAAAAAAAAAAAA", "AHBQLBHAHBQLBHAAAAAAAAAAAAA", "AHBQLBHAHBQLBHAAAAAAAAAAAAA", "AHBQLBHAHBQLBHAAAAAAAAAAAAA", "AGGGGGGAGGGGGGAAAAAAAAAAAAA", "AAAAAAEAEAAAAAAAAAAAAAAAAAA")
            .aisle("BDDDDDDDDDDDDDDDDDDDDDDDDDB", "BDDDDDDDDDDDDDDDDDDDDDDDDDB", "AEPPPPEEEPPPPEAAAAAUAAASAAA", "AEQQQQEEEQQQQEAAAAAUAAATAAA", "AEGGGGEEEGGGGEAAAAAUAAAUAAA", "ARHBBHRARHBBHRAAAAAUAAAUAAA", "ARHBBHRARHBBHRAAAAAUAAAUAAA", "ARHBBHRARHBBHRAAAAAUAAAUAAA", "ARHBBHRARHBBHRAAAAAAAAAAAAA", "ARHBBHRARHBBHRAAAAAAAAAAAAA", "ARHBBHRARHBBHRAAAAAAAAAAAAA", "AEGBBGEEEGBBGEAAAAAAAAAAAAA", "ARHBBHRARHBBHRAAAAAAAAAAAAA", "ARHBBHRARHBBHRAAAAAAAAAAAAA", "ARHBBHRARHBBHRAAAAAAAAAAAAA", "ARHBBHRARHBBHRAAAAAAAAAAAAA", "ARHBBHRARHBBHRAAAAAAAAAAAAA", "AEGBBGEEEGBBGEAAAAAAAAAAAAA", "ARHBBHRARHBBHRAAAAAAAAAAAAA", "ARHBBHRARHBBHRAAAAAAAAAAAAA", "ARHBBHRARHBBHRAAAAAAAAAAAAA", "ARHBBHRARHBBHRAAAAAAAAAAAAA", "ARHBBHRARHBBHRAAAAAAAAAAAAA", "ARHBBHRARHBBHRAAAAAAAAAAAAA", "AEGGGGEAEGGGGEAAAAAAAAAAAAA", "AEEEEEEEEEEEEEAAAAAAAAAAAAA")
            .aisle("BDDDDDDDDDDDDDDDDDDDDDDDDDB", "BDDDDDDDDDDDDDDDDDDDDDDDDDB", "AAEPPEAAAEPPEAAAAAVVVTVVVAA", "AAEQQEAAAEQQEAAAAAVVVTVVVAA", "AAEGGEAAAEGGEAAAAAVVVTVVVAA", "AARHHRAAARHHRAAAAAVVVTVVVAA", "AARHHRAAARHHRAAAAAVVVTVVVAA", "AARHHRAAARHHRAAAAAAUATAUAAA", "AARHHRAAARHHRAAAAAAAATAAAAA", "AARHHTTTTTHHTTTTTTTTTTAAAAA", "AARHHRAAARHHRAAAAAAAAAAAAAA", "AAEGGEAAAEGGEAAAAAAAAAAAAAA", "AARHHRAAARHHRAAAAAAAAAAAAAA", "AARHHRAAARHHRAAAAAAAAAAAAAA", "AARHHRAAARHHRAAAAAAAAAAAAAA", "AARHHRAAARHHRAAAAAAAAAAAAAA", "AARHHRAAARHHRAAAAAAAAAAAAAA", "AAEGGEAAAEGGEAAAAAAAAAAAAAA", "AARHHRAAARHHRAAAAAAAAAAAAAA", "AARHHRAAARHHRAAAAAAAAAAAAAA", "AARHHRAAARHHRAAAAAAAAAAAAAA", "AARHHRAAARHHRAAAAAAAAAAAAAA", "AARHHRAAARHHRAAAAAAAAAAAAAA", "AARHHRAAARHHRAAAAAAAAAAAAAA", "AAEGGEAAAEGGEAAAAAAAAAAAAAA", "AAEAAEAAAEAAEAAAAAAAAAAAAAA")
            .aisle("BDDDDDDDDDDDDDDDDDDDDDDDDDB", "BDDDDDDDDDDDDDDDDDDDDDDDDDB", "AAASAEASAEASASASAUVVVVVVVUA", "AAASAEASAEASASASAUVLLLLLVUA", "AAASAEASAEASASASAUVLALALVUA", "AAASASASASASASASAUVLALALVUA", "AAASASASASASASASAUVVVLVVVUA", "AAASSSSSSSSSSSSSSUUUTLTUUUA", "AAATTTTTTTTTTTTTTTTTTLTAAAA", "AAATLLLLLLLLLLLLLLLLLLTAAAA", "AAATTTTTTTTTTTTTTTTTTTAAAAA", "AAAAAEAAAEAAAAAAAAAAAAAAAAA", "AAAAAAAAAAAAAAAAAAAAAAAAAAA", "AAAAAAAAAAAAAAAAAAAAAAAAAAA", "AAAAAAAAAAAAAAAAAAAAAAAAAAA", "AAAAAAAAAAAAAAAAAAAAAAAAAAA", "AAAAAAAAAAAAAAAAAAAAAAAAAAA", "AAAAAEAAAEAAAAAAAAAAAAAAAAA", "AAAAAAAAAAAAAAAAAAAAAAAAAAA", "AAAAAAAAAAAAAAAAAAAAAAAAAAA", "AAAAAAAAAAAAAAAAAAAAAAAAAAA", "AAAAAAAAAAAAAAAAAAAAAAAAAAA", "AAAAAAAAAAAAAAAAAAAAAAAAAAA", "AAAAAAAAAAAAAAAAAAAAAAAAAAA", "AAAAAAAAAAAAAAAAAAAAAAAAAAA", "AAAAAEAAAEAAAAAAAAAAAAAAAAA")
            .aisle("BDDDDDDDDDDDDDDDDDDDDDDDDDB", "BDDDDDDDDDDDDDDDDDDDDDDDDDB", "AAEPPEAAAEPPEAAAAAVVVVVVVAA", "AAEQQEAAAEQQEAAAAAVLULULVAA", "AAEGGEAAAEGGEAAAAAVAUAUAVAA", "AARHHRAAARHHRAAAAAVAUAUAVAA", "AARHHRAAARHHRAAAAAVVVVVVVAA", "AARHHRAAARHHRAAAAAAUATAUAAA", "AARHHRAAARHHRAAAAAAAATAAAAA", "AARHHTTTTTHHTTTTTTTTTTAAAAA", "AARHHRAAARHHRAAAAAAAAAAAAAA", "AAEGGEAAAEGGEAAAAAAAAAAAAAA", "AARHHRAAARHHRAAAAAAAAAAAAAA", "AARHHRAAARHHRAAAAAAAAAAAAAA", "AARHHRAAARHHRAAAAAAAAAAAAAA", "AARHHRAAARHHRAAAAAAAAAAAAAA", "AARHHRAAARHHRAAAAAAAAAAAAAA", "AAEGGEAAAEGGEAAAAAAAAAAAAAA", "AARHHRAAARHHRAAAAAAAAAAAAAA", "AARHHRAAARHHRAAAAAAAAAAAAAA", "AARHHRAAARHHRAAAAAAAAAAAAAA", "AARHHRAAARHHRAAAAAAAAAAAAAA", "AARHHRAAARHHRAAAAAAAAAAAAAA", "AARHHRAAARHHRAAAAAAAAAAAAAA", "AAEGGEAAAEGGEAAAAAAAAAAAAAA", "AAEAAEAAAEAAEAAAAAAAAAAAAAA")
            .aisle("BDDDDDDDDDDDDDDDDDDDDDDDDDB", "BDDDDDDDDDDDDDDDDDDDDDDDDDB", "AEPPPPEEEPPPPEAAAAVVVVVVVAA", "AEQQQQEEEQQQQEAAAAVLLLLLVAA", "AEGGGGEEEGGGGEAAAAVLALALVAA", "ARHBBHRARHBBHRAAAAVLALALVAA", "ARHBBHRARHBBHRAAAAVVVVVVVAA", "ARHBBHRARHBBHRAAAAAUAAAUAAA", "ARHBBHRARHBBHRAAAAAAAAAAAAA", "ARHBBHRARHBBHRAAAAAAAAAAAAA", "ARHBBHRARHBBHRAAAAAAAAAAAAA", "AEGBBGEEEGBBGEAAAAAAAAAAAAA", "ARHBBHRARHBBHRAAAAAAAAAAAAA", "ARHBBHRARHBBHRAAAAAAAAAAAAA", "ARHBBHRARHBBHRAAAAAAAAAAAAA", "ARHBBHRARHBBHRAAAAAAAAAAAAA", "ARHBBHRARHBBHRAAAAAAAAAAAAA", "AEGBBGEEEGBBGEAAAAAAAAAAAAA", "ARHBBHRARHBBHRAAAAAAAAAAAAA", "ARHBBHRARHBBHRAAAAAAAAAAAAA", "ARHBBHRARHBBHRAAAAAAAAAAAAA", "ARHBBHRARHBBHRAAAAAAAAAAAAA", "ARHBBHRARHBBHRAAAAAAAAAAAAA", "ARHBBHRARHBBHRAAAAAAAAAAAAA", "AEGGGGEAEGGGGEAAAAAAAAAAAAA", "AEEEEEEEEEEEEEAAAAAAAAAAAAA")
            .aisle("BDDDDDDDDDDDDDDDDDDDDDDDDDB", "BDDDDDDDDDDDDDDDDDDDDDDDDDB", "APPPPPPAPPPPPPAAAAVVVVVVVAA", "AQQQQQQAQQQQQQAAAAVLULULVAA", "AGGGGGGAGGGGGGAAAAVAUAUAVAA", "AHBLQBHAHBLQBHAAAAVAUAUAVAA", "AHBLQBHAHBLQBHAAAAVVVVVVVAA", "AHBLQBHAHBLQBHAAAAAUAAAUAAA", "AHBLQBHAHBLQBHAAAAAAAAAAAAA", "AHBLQBHAHBLQBHAAAAAAAAAAAAA", "AHBLQBHAHBLQBHAAAAAAAAAAAAA", "AGBLQBGAGBLQBGAAAAAAAAAAAAA", "AHBLQBHAHBLQBHAAAAAAAAAAAAA", "AHBLQBHAHBLQBHAAAAAAAAAAAAA", "AHBLQBHAHBLQBHAAAAAAAAAAAAA", "AHBLQBHAHBLQBHAAAAAAAAAAAAA", "AHBLQBHAHBLQBHAAAAAAAAAAAAA", "AGBLQBGAGBLQBGAAAAAAAAAAAAA", "AHBLQBHAHBLQBHAAAAAAAAAAAAA", "AHBLQBHAHBLQBHAAAAAAAAAAAAA", "AHBLQBHAHBLQBHAAAAAAAAAAAAA", "AHBLQBHAHBLQBHAAAAAAAAAAAAA", "AHBLQBHAHBLQBHAAAAAAAAAAAAA", "AHBLQBHAHBLQBHAAAAAAAAAAAAA", "AGGGGGGAGGGGGGAAAAAAAAAAAAA", "AAAAAAEAEAAAAAAAAAAAAAAAAAA")
            .aisle("BDDDDDDDDDDDDDDDDDDDDDDDDDB", "BDDDDDDDDDDDDDDDDDDDDDDDDDB", "APPPPPPAPPPPPPAAAUVVVVVVVUA", "AQQQQQQAQQQQQQAAAUVLLLLLVUA", "AGGGGGGAGGGGGGAAAUVLALALVUA", "AHBQLBHAHBQLBHAAAUVLALALVUA", "AHBQLBHAHBQLBHAAAUVVVVVVVUA", "AHBQLBHAHBQLBHAAAUUUAAAUUUA", "AHBQLBHAHBQLBHAAAAAAAAAAAAA", "AHBQLBHAHBQLBHAAAAAAAAAAAAA", "AHBQLBHAHBQLBHAAAAAAAAAAAAA", "AGBQLBGAGBQLBGAAAAAAAAAAAAA", "AHBQLBHAHBQLBHAAAAAAAAAAAAA", "AHBQLBHAHBQLBHAAAAAAAAAAAAA", "AHBQLBHAHBQLBHAAAAAAAAAAAAA", "AHBQLBHAHBQLBHAAAAAAAAAAAAA", "AHBQLBHAHBQLBHAAAAAAAAAAAAA", "AGBQLBGAGBQLBGAAAAAAAAAAAAA", "AHBQLBHAHBQLBHAAAAAAAAAAAAA", "AHBQLBHAHBQLBHAAAAAAAAAAAAA", "AHBQLBHAHBQLBHAAAAAAAAAAAAA", "AHBQLBHAHBQLBHAAAAAAAAAAAAA", "AHBQLBHAHBQLBHAAAAAAAAAAAAA", "AHBQLBHAHBQLBHAAAAAAAAAAAAA", "AGGGGGGAGGGGGGAAAAAAAAAAAAA", "AAAAAAEAEAAAAAAAAAAAAAAAAAA")
            .aisle("BDDDDDDDDDDDDDDDDDDDDDDDDDB", "BDDDDDDDDDDDDDDDDDDDDDDDDDB", "AEPPPPEAEPPPPEAAAAVVVVVVVAA", "AEQQQQEAEQQQQEAAAAVVVWVVVAA", "AEGGGGEAEGGGGEAAAAVVVVVVVAA", "ARHBBHRARHBBHRAAAAVVVVVVVAA", "ARHBBHRARHBBHRAAAAVVVVVVVAA", "ARHBBHRARHBBHRAAAAAUAAAUAAA", "ARHBBHRARHBBHRAAAAAAAAAAAAA", "ARHBBHRARHBBHRAAAAAAAAAAAAA", "ARHBBHRARHBBHRAAAAAAAAAAAAA", "AEGBBGEAEGBBGEAAAAAAAAAAAAA", "ARHBBHRARHBBHRAAAAAAAAAAAAA", "ARHBBHRARHBBHRAAAAAAAAAAAAA", "ARHBBHRARHBBHRAAAAAAAAAAAAA", "ARHBBHRARHBBHRAAAAAAAAAAAAA", "ARHBBHRARHBBHRAAAAAAAAAAAAA", "AEGBBGEAEGBBGEAAAAAAAAAAAAA", "ARHBBHRARHBBHRAAAAAAAAAAAAA", "ARHBBHRARHBBHRAAAAAAAAAAAAA", "ARHBBHRARHBBHRAAAAAAAAAAAAA", "ARHBBHRARHBBHRAAAAAAAAAAAAA", "ARHBBHRARHBBHRAAAAAAAAAAAAA", "ARHBBHRARHBBHRAAAAAAAAAAAAA", "AEGGGGEAEGGGGEAAAAAAAAAAAAA", "AEEEEEEAEEEEEEAAAAAAAAAAAAA")
            .aisle("BDDDDDDDDDDDDDDDDDDDDDDDDDB", "BDDDDDDDDDDDDDDDDDDDDDDDDDB", "AAEPPEAAAEPPEAAAAAAUAAAUAAA", "AAEQQEAAAEQQEAAAAAAUAAAUAAA", "AAEGGEAAAEGGEAAAAAAUAAAUAAA", "AARHHRAAARHHRAAAAAAUAAAUAAA", "AARHHRAAARHHRAAAAAAUAAAUAAA", "AARHHRAAARHHRAAAAAAUAAAUAAA", "AARHHRAAARHHRAAAAAAAAAAAAAA", "AARHHRAAARHHRAAAAAAAAAAAAAA", "AARHHRAAARHHRAAAAAAAAAAAAAA", "AAEGGEAAAEGGEAAAAAAAAAAAAAA", "AARHHRAAARHHRAAAAAAAAAAAAAA", "AARHHRAAARHHRAAAAAAAAAAAAAA", "AARHHRAAARHHRAAAAAAAAAAAAAA", "AARHHRAAARHHRAAAAAAAAAAAAAA", "AARHHRAAARHHRAAAAAAAAAAAAAA", "AAEGGEAAAEGGEAAAAAAAAAAAAAA", "AARHHRAAARHHRAAAAAAAAAAAAAA", "AARHHRAAARHHRAAAAAAAAAAAAAA", "AARHHRAAARHHRAAAAAAAAAAAAAA", "AARHHRAAARHHRAAAAAAAAAAAAAA", "AARHHRAAARHHRAAAAAAAAAAAAAA", "AARHHRAAARHHRAAAAAAAAAAAAAA", "AAEGGEAAAEGGEAAAAAAAAAAAAAA", "AAEAAEAAAEAAEAAAAAAAAAAAAAA")
            .aisle("BBBBBBBBBBBBBBBBBBBBBBBBBBB", "BBBBBBBBBBBBBBBBBBBBBBBBBBB", "AAAAAAAAAAAAAAAAAAAAAAAAAAA", "AAAAAAAAAAAAAAAAAAAAAAAAAAA", "AAAAAAAAAAAAAAAAAAAAAAAAAAA", "AAAAAAAAAAAAAAAAAAAAAAAAAAA", "AAAAAAAAAAAAAAAAAAAAAAAAAAA", "AAAAAAAAAAAAAAAAAAAAAAAAAAA", "AAAAAAAAAAAAAAAAAAAAAAAAAAA", "AAAAAAAAAAAAAAAAAAAAAAAAAAA", "AAAAAAAAAAAAAAAAAAAAAAAAAAA", "AAAAAAAAAAAAAAAAAAAAAAAAAAA", "AAAAAAAAAAAAAAAAAAAAAAAAAAA", "AAAAAAAAAAAAAAAAAAAAAAAAAAA", "AAAAAAAAAAAAAAAAAAAAAAAAAAA", "AAAAAAAAAAAAAAAAAAAAAAAAAAA", "AAAAAAAAAAAAAAAAAAAAAAAAAAA", "AAAAAAAAAAAAAAAAAAAAAAAAAAA", "AAAAAAAAAAAAAAAAAAAAAAAAAAA", "AAAAAAAAAAAAAAAAAAAAAAAAAAA", "AAAAAAAAAAAAAAAAAAAAAAAAAAA", "AAAAAAAAAAAAAAAAAAAAAAAAAAA", "AAAAAAAAAAAAAAAAAAAAAAAAAAA", "AAAAAAAAAAAAAAAAAAAAAAAAAAA", "AAAAAAAAAAAAAAAAAAAAAAAAAAA", "AAAAAAAAAAAAAAAAAAAAAAAAAAA")
                .where("A", Predicates.any())
                .where("W", Predicates.controller(Predicates.blocks(definition.get())))
                .where("B", Predicates.blocks("kubejs:orbital_space_containment_casing"))
                .where("D", Predicates.blocks("kubejs:reinforced_base_casing"))
                .where("E", Predicates.blocks("gtceu:cosmic_neutronium_frame"))
                .where("F", Predicates.blocks("gtceu:high_temperature_smelting_casing"))
                .where("G", Predicates.blocks("kubejs:covalent_conducting_casing"))
                .where("H", Predicates.blocks("gtceu:clean_machine_casing"))
                .where("I", Predicates.blocks("gtceu:stainless_steel_turbine_casing"))
                .where("J", Predicates.blocks("kubejs:awakened_draconium_coil_block"))
                .where("K", Predicates.blocks("kubejs:ultimate_engine_intake_casing"))
                .where("L", Predicates.blocks("kubejs:orbital_pipe_casing"))
                .where("M", Predicates.blocks("gtceu:solid_machine_casing"))
                .where("N", Predicates.blocks("kubejs:refracting_hastelloy_c276_casing"))
                .where("O", Predicates.blocks("kubejs:temperature_proof_potin_casing"))
                .where("P", Predicates.blocks("kubejs:space_resistant_orbital_casing"))
                .where("Q", Predicates.blocks("gtceu:heat_vent"))
                .where("R", Predicates.blocks("gtceu:hsla_steel_frame"))
                .where("S", Predicates.blocks("gtceu:neutronium_frame"))
                .where("T", Predicates.blocks("kubejs:neutronium_casing"))
                .where("U", Predicates.blocks("gtceu:hastelloy_x_frame"))
                .where("V", Predicates.blocks("kubejs:supercritical_cryo_cooled_casing")
                    .or(Predicates.abilities(
                        PartAbility.EXPORT_ITEMS,
                        PartAbility.IMPORT_ITEMS,
                        PartAbility.INPUT_LASER,
                        PartAbility.INPUT_ENERGY,
                        PartAbility.IMPORT_FLUIDS,
                        PartAbility.EXPORT_FLUIDS))
                )
            .build()
        )
        .workableCasingModel("kubejs:block/casings/supercritical_cryo_cooled_casing", 'kubejs:block/gui/machine_controller/mega_distillation_facility')
})
