GTCEuStartupEvents.registry('gtceu:recipe_type', event => {
    event.create('eternity_recursion_engine')
        .category('drack')
        .setEUIO('in')
        .setMaxIOSize(5, 5, 4, 4)
        .setProgressBar(GuiTextures.PROGRESS_BAR_FUSION, FillDirection.LEFT_TO_RIGHT)
        .setSound(GTSoundEntries.REPLICATOR)
})




GTCEuStartupEvents.registry('gtceu:machine', event => {
    event.create('eternity_recursion_engine', 'multiblock')
        .rotationState(RotationState.NON_Y_AXIS)
        .recipeType('eternity_recursion_engine')
        .recipeModifiers([GTRecipeModifiers.OC_NON_PERFECT, GTRecipeModifiers.BATCH_MODE])
        .appearanceBlock(() => Block.getBlock('gtceu:block/casings/hpca/advanced_computer_casing'))
        .pattern(definition => FactoryBlockPattern.start()
            .aisle("############BBBBCBBBB############", "############BBBBCBBBB############", "################F################", "################F################", "################F################", "################F################", "################F################", "################F################", "################F################", "################F################", "################F################", "################F################", "################F################", "################F################", "################F################", "################F################", "################G################", "################G################", "################G################", "#############GGGGGGG#############", "################G################", "################G################", "################G################", "#################################", "#################################", "#################################", "#################################", "#################################", "#################################", "#################################", "#################################", "#################################", "#################################", "#################################", "#################################", "#################################")
            .aisle("##########BBHHHHCHHHHBB##########", "##########BBHHHHCHHHHBB##########", "#################################", "#################################", "#################################", "#################################", "#################################", "#################################", "#################################", "#################################", "#################################", "#################################", "#################################", "################G################", "################G################", "################G################", "###############IJI###############", "##############IIJII##############", "#############IIIJIII#############", "##########GGGJJJJJJJGGG##########", "#############IIIJIII#############", "##############IIJII##############", "###############IJI###############", "################G################", "################G################", "################G################", "#################################", "#################################", "#################################", "#################################", "#################################", "#################################", "#################################", "#################################", "#################################", "#################################")
            .aisle("########BBHHHHHHCHHHHHHBB########", "########BBHHHHHHCHHHHHHBB########", "#################################", "#################################", "#################################", "#################################", "#################################", "#################################", "#################################", "#################################", "#################################", "################G################", "################G################", "##############IIJII##############", "############IIIIJIIII############", "###########IIIIIJIIIII###########", "###########IIII###IIII###########", "##########IIII#####IIII##########", "##########III#######III##########", "########GGJJJ#######JJJGG########", "##########III#######III##########", "##########IIII#####IIII##########", "###########IIII####III###########", "###########IIIIIJIIIII###########", "############IIIIJIIII############", "##############IIJII##############", "################G################", "################G################", "#################################", "#################################", "#################################", "#################################", "#################################", "#################################", "#################################", "#################################")
            .aisle("######BBHHHHHHHHCHHHHHHHHBB######", "######BBHHHHHHHHCHHHHHHHHBB######", "#################################", "#################################", "#################################", "#################################", "#################################", "#################################", "#################################", "#################################", "################G################", "##############IIJII##############", "############IIIIJIIII############", "###########III#####III###########", "##########II#########II##########", "#########II###########II#########", "#########II###########II#########", "########II#############II########", "########II#############II########", "#######GJJ#############JJG#######", "########II#############II########", "########II#############II########", "#########II###########II#########", "#########II###########II#########", "##########II#########II##########", "###########III#####III###########", "############IIIIJIIII############", "##############IIJII##############", "################G################", "#################################", "#################################", "#################################", "#################################", "#################################", "#################################", "#################################")
            .aisle("#####BHHHHHHHCCCCCCCHHHHHHHB#####", "#####BHHHHHHHCCCCCCCHHHHHHHB#####", "################F################", "################F################", "################F################", "################F################", "################F################", "################F################", "################F################", "################G################", "#############IIIJIII#############", "###########III#####III###########", "##########II#########II##########", "#########II###########II#########", "########II#############II########", "########I###############I########", "#######II###############II#######", "#######I#################I#######", "#######I#################I#######", "######GJ#################JG######", "#######I#################I#######", "#######I#################I#######", "#######II###############II#######", "########I###############I########", "########II#############II########", "#########II###########II#########", "##########II#########II##########", "###########III#####III###########", "#############IIIJIII#############", "################G################", "#################################", "#################################", "#################################", "#################################", "#################################", "#################################")
            .aisle("####BHHHHHHCCHHHCHHHCCHHHHHHB####", "####BHHHHHHCCHHHCHHHCCHHHHHHB####", "#################################", "#################################", "#################################", "#################################", "#################################", "#################################", "################G################", "############IIIIJIIII############", "##########III#######III##########", "#########II###########II#########", "########II#############II########", "#######II###############II#######", "#######I#################I#######", "######II#################II######", "######I###################I######", "######I###################I######", "######I###################I######", "#####GJ###################JG#####", "######I###################I######", "######I###################I######", "######I###################I######", "######II#################II######", "#######I#################I#######", "#######II###############II#######", "########II#############II########", "#########II###########II#########", "##########III#######III##########", "############IIIIJIIII############", "################G################", "#################################", "#################################", "#################################", "#################################", "#################################")
            .aisle("###BHHHHHCCHHHHHCHHHHHCCHHHHHB###", "###BHHHHHCCHHHHHCHHHHHCCHHHHHB###", "#################################", "#################################", "#################################", "#################################", "#################################", "################G################", "############IIIIJIIII############", "##########II#########II##########", "#########I#############I#########", "########I###############I########", "#######I#################I#######", "######I###################I######", "######I###################I######", "#####I#####################I#####", "#####I#####################I#####", "#####I#####################I#####", "#####I#####################I#####", "####GJ#####################JG####", "#####I#####################I#####", "#####I#####################I#####", "#####I#####################I#####", "#####I#####################I#####", "######I###################I######", "######I###################I######", "#######I#################I#######", "########I###############I########", "#########I#############I#########", "##########II#########II##########", "############IIIIJIIII############", "################G################", "#################################", "#################################", "#################################", "#################################")
            .aisle("###BHHHHCHHHHHHHCHHHHHHHCHHHHB###", "###BHHHHCHHHHHHHCHHHHHHHCHHHHB###", "#################################", "#################################", "#################################", "#################################", "################G################", "#############IIIJIII#############", "##########III#######III##########", "#########I#############I#########", "########I###############I########", "#######I#################I#######", "######I###################I######", "#####I#####################I#####", "#####I#####################I#####", "#####I#####################I#####", "####I#######################I####", "####I#######################I####", "####I#######################I####", "###GJ#######################JG###", "####I#######################I####", "####I#######################I####", "####I#######################I####", "#####I#####################I#####", "#####I#####################I#####", "#####I#####################I#####", "######I###################I######", "#######I#################I#######", "########I###############I########", "#########I#############I#########", "##########III#######III##########", "#############IIIJIII#############", "################G################", "#################################", "#################################", "#################################")
            .aisle("##BHHHHCHHHHHHCCCCCHHHHHHCHHHHB##", "##BHHHHCHHHHHHCCCCCHHHHHHCHHHHB##", "################F################", "################F################", "################F################", "################G################", "##############IIJII##############", "###########III#####III###########", "#########II###########II#########", "########I###############I########", "#######I#################I#######", "######I###################I######", "#####I#####################I#####", "#####I#####################I#####", "####I#######################I####", "####I#######################I####", "####I#######################I####", "###I#########################I###", "###I#########################I###", "##GJ#########################JG##", "###I#########################I###", "###I#########################I###", "####I#######################I####", "####I#######################I####", "####I#######################I####", "#####I#####################I#####", "#####I#####################I#####", "######I###################I######", "#######I#################I#######", "########I###############I########", "#########II###########II#########", "###########III#####III###########", "##############IIJII##############", "################G################", "#################################", "#################################")
            .aisle("##BHHHCHHHHHCCHHCHHCCHHHHHCHHHB##", "##BHHHCHHHHHCCHHCHHCCHHHHHCHHHB##", "#################################", "#################################", "#################################", "################G################", "############IIIIJIIII############", "##########II#########II##########", "########II#############II########", "#######I#################I#######", "######I###################I######", "#####I#####################I#####", "#####I###############ZLZ###I#####", "####I################ZZL####I####", "####I################ZZL####I####", "###I#########################I###", "###I#########################I###", "###I#########################I###", "###I#########################I###", "##GJ#########################JG##", "###I#########################I###", "###I#########################I###", "###I#########################I###", "###I#########################I###", "####I#######################I####", "####I#######################I####", "#####I#####################I#####", "#####I#####################I#####", "######I###################I######", "#######I#################I#######", "########II#############II########", "##########II#########II##########", "############IIIIJIIII############", "################G################", "#################################", "#################################")
            .aisle("#BHHHHCHHHCCHHHHCHHHHCCHHHCHHHHB#", "#BHHHHCHHHCCHHHHCHHHHCCHHHCHHHHB#", "#################################", "#################################", "################G################", "##############IIJII##############", "###########III#####III###########", "#########II###########II#########", "#######II###############II#######", "######I###################I######", "#####I#####################I#####", "#####I#####################I#####", "####I################ZMZ####I####", "####I################ZZL####I####", "###I#################LML#####I###", "###I#########################I###", "###I#########################I###", "##I###########################I##", "##I###########################I##", "#GJ###########################JG#", "##I###########################I##", "##I###########################I##", "###I#########################I###", "###I######NNN################I###", "###I######NNN################I###", "####I#####NNN###############I####", "####I#######################I####", "#####I#####################I#####", "#####I#####################I#####", "######I###################I######", "#######II###############II#######", "#########II###########II#########", "###########III#####III###########", "##############IIJII##############", "################G################", "#################################")
            .aisle("#BHHHCHHHHCHHHHHCHHHHHCHHHHCHHHB#", "#BHHHCHHHHCHHHHHCHHHHHCHHHHCHHHB#", "#################################", "#################################", "################G################", "############IIIIJIIII############", "##########II#########II##########", "########II#############II########", "#######I#################I#######", "######I###################I######", "#####I#####################I#####", "####I#######################I####", "####I################LLZ####I####", "###I#################LZZ#####I###", "###I#################LLZ#####I###", "##I###########################I##", "##I###########################I##", "##I###########################I##", "##I###########################I##", "#GJ###########################JG#", "##I###########################I##", "##I###########################I##", "##I###########################I##", "##I#######NNN#################I##", "###I######NNN################I###", "###I######NNN################I###", "####I#######################I####", "####I#######################I####", "#####I#####################I#####", "######I###################I######", "#######I#################I#######", "########II#############II########", "##########II#########II##########", "############IIIIJIIII############", "################G################", "#################################")
            .aisle("BHHHHCHHHCHHHHCCCCCHHHHCHHHCHHHHB", "BHHHHCHHHCHHHHCCCCCHHHHCHHHCHHHHB", "################F################", "################F################", "################G################", "###########IIIIIJIIIII###########", "#########II###########II#########", "########I###############I########", "######II#################II######", "#####I#####################I#####", "#####I#####################I#####", "####I#######################I####", "###I#########################I###", "###I#########################I###", "##I###########################I##", "##I###########################I##", "##I###########################I##", "##I###########################I##", "##I###########################I##", "#GJ###########################JG#", "##I###########################I##", "##I###########################I##", "##I###########################I##", "##I#######NNN#################I##", "##I#######NNN#################I##", "###I######NNN################I###", "###I#########################I###", "####I#######################I####", "#####I#####################I#####", "#####I#####################I#####", "######II#################II######", "########I###############I########", "#########II###########II#########", "###########IIIIIJIIIII###########", "################G################", "#################################")
            .aisle("BHHHCHHHHCHHHCHHCHHCHHHCHHHHCHHHB", "BHHHCHHHHCHHHCHHCHHCHHHCHHHHCHHHB", "#################################", "################G################", "###############IJI###############", "###########IIII###IIII###########", "#########II###########II#########", "#######II###############II#######", "######I###################I######", "#####I#####################I#####", "####I#######################I####", "####I#######################I####", "###I#########################I###", "###I#########################I###", "##I###########################I##", "##I###########################I##", "##I###########################I##", "##I###########################I##", "#I#############OOO#############I#", "GJ#############OOO#############JG", "#I#############OOO#############I#", "##I###########################I##", "##I###########################I##", "##I###########################I##", "##I###########################I##", "###I#########################I###", "###I#########################I###", "####I#######################I####", "####I#######################I####", "#####I#####################I#####", "######I###################I######", "#######II###############II#######", "#########II###########II#########", "###########IIII###IIII###########", "###############IJI###############", "################G################")
            .aisle("BHHHCHHHCHHHCHHHCHHHCHHHCHHHCHHHB", "BHHHCHHHCHHHCHHHCHHHCHHHCHHHCHHHB", "#################################", "################G################", "##############IIJII##############", "##########IIII#####IIII##########", "########II#############II########", "#######I#################I#######", "######I###################I######", "#####I#####################I#####", "####I#######################I####", "###I#########################I###", "###I#########################I###", "##I###########################I##", "##I###########################I##", "##I###########################I##", "##I###########################I##", "#I#############OOO#############I#", "#I############OOOOO############I#", "GJ############OOOOO############JG", "#I############OOOOO############I#", "#I#############OOO#############I#", "##I###########################I##", "##I###########################I##", "##I###########################I##", "##I###########################I##", "###I#########################I###", "###I#########################I###", "####I#######################I####", "#####I#####################I#####", "######I###################I######", "#######I#################I#######", "########II#############II########", "##########IIII#####IIII##########", "##############IIJII##############", "################G################")
            .aisle("BHHHCHHHCHHHCHHHCHHHCHHHCHHHCHHHB", "BHHHCHHHCHHHCHHHCHHHCHHHCHHHCHHHB", "#################################", "################G################", "#############IIIJIII#############", "##########III#######III##########", "########II#############II########", "#######I#################I#######", "######I###################I######", "#####I#####################I#####", "####I#######################I####", "###I#########################I###", "###I#########################I###", "##I###########################I##", "##I###########################I##", "##I###########################I##", "#I#############OOO#############I#", "#I############OOOOO############I#", "#I###########OOOOOOO###########I#", "GJ########PQ#OOOOOOO###########JG", "#I########PQ#OOOOOOO###########I#", "#I############OOOOO############I#", "#I#############OOO#############I#", "##I###########################I##", "##I###########################I##", "##I###########################I##", "###I#########################I###", "###I#########################I###", "####I#######################I####", "#####I#####################I#####", "######I###################I######", "#######I#################I#######", "########II#############II########", "##########III#######III##########", "#############IIIJIII#############", "################G################")
            .aisle("CCCCCCCCCCCCCCCCCCCCCCCCCCCCCCCCC", "CCCCCCCCCCCCCCCCCCCCCCCCCCCCCCCCC", "F###F###F###F###F###F###F###F###F", "F###F###F###FGGGGGGGF###F###F###F", "F###F###F#GGGJJJJJJJGGG#F###F###F", "F###F###GGJJJ#######JJJGG###F###F", "F###F##GJJ#############JJG##F###F", "F###F#GJ#################JG#F###F", "F####GJ###################JGF###F", "F###GJ#####################JG###F", "F##GJ#######################JG##F", "F#GJ#########################JG#F", "F#GJ#########################JG#F", "FGJ###########################JGF", "FGJ###########################JGF", "FGJ###########################JGF", "GJ#############OOO#############JG", "GJ############OOOOO############JG", "GJ###########OOOOOOO###########JG", "GJ########PQ#OOOOOOO###########JG", "GJ########PQ#OOOOOOO###########JG", "GJ############OOOOO############JG", "GJ#############OOO#############JG", "#GJ###########################JG#", "#GJ###########################JG#", "#GJ###########################JG#", "##GJ#########################JG##", "##GJ#########################JG##", "###GJ#######################JG###", "####GJ#####################JG####", "#####GJ###################JG#####", "######GJ#################JG######", "#######GJJ#############JJG#######", "########GGJJJ#######JJJGG########", "##########GGGJJJJJJJGGG##########", "#############GGGGGGG#############")
            .aisle("BHHHCHHHCHHHCHHHCHHHCHHHCHHHCHHHB", "BHHHCHHHCHHHCHHHCHHHCHHHCHHHCHHHB", "#################################", "################G################", "#############IIIJIII#############", "##########III#######III##########", "########II#############II########", "#######I#################I#######", "######I###################I######", "#####I#####################I#####", "####I#######################I####", "###I#########################I###", "###I#########################I###", "##I###########################I##", "##I###########################I##", "##I###########################I##", "#I#############OOO#############I#", "#I############OOOOO############I#", "#I###########OOOOOOO###########I#", "GJ###########OOOOOOO###########JG", "#I###########OOOOOOO###########I#", "#I############OOOOO############I#", "#I#############OOO#############I#", "##I###########################I##", "##I###########################I##", "##I###########################I##", "###I#########################I###", "###I#########################I###", "####I#######################I####", "#####I#####################I#####", "######I###################I######", "#######I#################I#######", "########II#############II########", "##########III#######III##########", "#############IIIJIII#############", "################G################")
            .aisle("BHHHCHHHCHHHCHHHCHHHCHHHCHHHCHHHB", "BHHHCHHHCHHHCHHHCHHHCHHHCHHHCHHHB", "#################################", "################G################", "##############IIJII##############", "##########IIII######III##########", "########II#############II########", "#######I#################I#######", "######I###################I######", "#####I#####################I#####", "####I#######################I####", "###I#########################I###", "###I#########################I###", "##I###########################I##", "##I###########################I##", "##I###########################I##", "##I###########################I##", "#I#############OOO#############I#", "#I############OOOOO############I#", "GJ############OOOOO############JG", "#I############OOOOO############I#", "#I#############OOO#############I#", "##I###########################I##", "##I###########################I##", "##I###########################I##", "##I###########################I##", "###I#########################I###", "###I#########################I###", "####I#######################I####", "#####I#####################I#####", "######I###################I######", "#######I#################I#######", "########II#############II########", "##########IIII#####IIII##########", "##############IIJII##############", "################G################")
            .aisle("BHHHCHHHHCHHHCHHCHHCHHHCHHHHCHHHB", "BHHHCHHHHCHHHCHHCHHCHHHCHHHHCHHHB", "#################################", "################G################", "###############IJI###############", "###########IIII####III###########", "#########II###########II#########", "#######II###############II#######", "######I###################I######", "#####I#####################I#####", "####I#######################I####", "####I#######################I####", "###I#########################I###", "###I#########################I###", "##I###########################I##", "##I###########################I##", "##I###########################I##", "##I###########################I##", "#I#############OOO#############I#", "GJ#############OOO#############JG", "#I#############OOO#############I#", "##I###########################I##", "##I###########################I##", "##I###########################I##", "##I###########################I##", "###I#########################I###", "###I#########################I###", "####I#######################I####", "####I#######################I####", "#####I#####################I#####", "######I###################I######", "#######II###############II#######", "#########II###########II#########", "###########IIII###IIII###########", "###############IJI###############", "################G################")
            .aisle("BHHHHCHHHCHHHHCCCCCHHHHCHHHCHHHHB", "BHHHHCHHHCHHHHCCCCCHHHHCHHHCHHHHB", "################F################", "################F################", "################G################", "###########IIIIIJIIIII###########", "#########II###########II#########", "########I###############I########", "######II#################II######", "#####I#####################I#####", "#####I#####################I#####", "####I#######################I####", "###I#########################I###", "###I#########################I###", "##I###########################I##", "##I###########################I##", "##I###########################I##", "##I###########################I##", "##I###########################I##", "#GJ###########################JG#", "##I###########################I##", "##I###########################I##", "##I###########################I##", "##I###########################I##", "##I###########################I##", "###I#########################I###", "###I#########################I###", "####I#######################I####", "#####I#####################I#####", "#####I#####################I#####", "######II#################II######", "########I###############I########", "#########II###########II#########", "###########IIIIIJIIIII###########", "################G################", "#################################")
            .aisle("#BHHHCHHHHCHHHHHCHHHHHCHHHHCHHHB#", "#BHHHCHHHHCHHHHHCHHHHHCHHHHCHHHB#", "#################################", "#################################", "################G################", "############IIIIJIIII############", "##########II#########II##########", "########II#############II########", "#######I#################I#######", "######I###################I######", "#####I#####################I#####", "####I#######################I####", "####I#######################I####", "###I#########################I###", "###I#########################I###", "##I###########################I##", "##I###########################I##", "##I###########################I##", "##I###########################I##", "#GJ###########################JG#", "##I###########################I##", "##I###########################I##", "##I###########################I##", "##I###########################I##", "###I#########################I###", "###I#########################I###", "####I#######################I####", "####I#######################I####", "#####I#####################I#####", "######I###################I######", "#######I#################I#######", "########II#############II########", "##########II#########II##########", "############IIIIJIIII############", "################G################", "#################################")
            .aisle("#BHHHHCHHHCCHHHHCHHHHCCHHHCHHHHB#", "#BHHHHCHHHCCHHHHCHHHHCCHHHCHHHHB#", "#################################", "#################################", "################G################", "##############IIJII##############", "###########III#####III###########", "#########II###########II#########", "#######II###############II#######", "######I###################I######", "#####I#####################I#####", "#####I#####################I#####", "####I#######################I####", "####I#######################I####", "###I#########################I###", "###I#########################I###", "###I#########################I###", "##I###########################I##", "##I###########################I##", "#GJ###########################JG#", "##I###########################I##", "##I###########################I##", "###I#########################I###", "###I#########################I###", "###I#########################I###", "####I#######################I####", "####I#######################I####", "#####I#####################I#####", "#####I#####################I#####", "######I###################I######", "#######II###############II#######", "#########II###########II#########", "###########III#####III###########", "##############IIJII##############", "################G################", "#################################")
            .aisle("##BHHHCHHHHHCCHHCHHCCHHHHHCHHHB##", "##BHHHCHHHHHCCHHCHHCCHHHHHCHHHB##", "#################################", "#################################", "#################################", "################G################", "############IIIIJIIII############", "##########II#########II##########", "########II#############II########", "#######I#################I#######", "######I###################I######", "#####I#####################I#####", "#####I#####################I#####", "####I#######################I####", "####I#######################I####", "###I#########################I###", "###I#########################I###", "###I###################RRR###I###", "###I###################RRR###I###", "##GJ###################RRR###JG##", "###I#########################I###", "###I#########################I###", "###I#########################I###", "###I#########################I###", "####I#######################I####", "####I#######################I####", "#####I#####################I#####", "#####I#####################I#####", "######I###################I######", "#######I#################I#######", "########II#############II########", "##########II#########II##########", "############IIIIJIIII############", "################G################", "#################################", "#################################")
            .aisle("##BHHHHCHHHHHHCCCCCHHHHHHCHHHHB##", "##BHHHHCHHHHHHCCCCCHHHHHHCHHHHB##", "################F################", "################F################", "################F################", "################G################", "##############IIJII##############", "###########III#####III###########", "#########II###########II#########", "########I###############I########", "#######I#################I#######", "######I###################I######", "#####I#####################I#####", "#####I#####################I#####", "####I#######################I####", "####I#######################I####", "####I#######################I####", "###I###################RRR###I###", "###I###################RRR###I###", "##GJ###################RMR###JG##", "###I#########################I###", "###I#########################I###", "####I#######################I####", "####I#######################I####", "####I#######################I####", "#####I#####################I#####", "#####I#####################I#####", "######I###################I######", "#######I#################I#######", "########I###############I########", "#########II###########II#########", "###########III#####III###########", "##############IIJII##############", "################G################", "#################################", "#################################")
            .aisle("###BHHHHCHHHHHHHCHHHHHHHCHHHHB###", "###BHHHHCHHHHHHHCHHHHHHHCHHHHB###", "#################################", "#################################", "#################################", "#################################", "################G################", "#############IIIJIII#############", "##########III#######III##########", "#########I#############I#########", "########I###############I########", "#######I#################I#######", "######I###################I######", "#####I#####################I#####", "#####I#####################I#####", "#####I#####################I#####", "####I#######################I####", "####I##################RRR##I####", "####I##################RRR##I####", "###GJ##################RRR##JG###", "####I#######################I####", "####I#######################I####", "####I#######################I####", "#####I#####################I#####", "#####I#####################I#####", "#####I#####################I#####", "######I###################I######", "#######I#################I#######", "########I###############I########", "#########I#############I#########", "##########III#######III##########", "#############IIIJIII#############", "################G################", "#################################", "#################################", "#################################")
            .aisle("###BHHHHHCCHHHHHCHHHHHCCHHHHHB###", "###BHHHHHCCHHHHHCHHHHHCCHHHHHB###", "#################################", "#################################", "#################################", "#################################", "#################################", "################G################", "############IIIIJIIII############", "##########II#########II##########", "#########I#############I#########", "########I###############I########", "#######I#################I#######", "######I###################I######", "######I###################I######", "#####I#####################I#####", "#####I#####################I#####", "#####I#####################I#####", "#####I#####################I#####", "####GJ#####################JG####", "#####I#####################I#####", "#####I#####################I#####", "#####I#####################I#####", "#####I#####################I#####", "######I###################I######", "######I###################I######", "#######I#################I#######", "########I###############I########", "#########I#############I#########", "##########II#########II##########", "############IIIIJIIII############", "################G################", "#################################", "#################################", "#################################", "#################################")
            .aisle("####BHHHHHHCCHHHCHHHCCHHHHHHB####", "####BHHHHHHCCHHHCHHHCCHHHHHHB####", "#################################", "#################################", "#################################", "#################################", "#################################", "#################################", "################G################", "############IIIIJIIII############", "##########III#######III##########", "#########II###########II#########", "########II#############II########", "#######II###############II#######", "#######I#################I#######", "######II#################II######", "######I###################I######", "######I###################I######", "######I###################I######", "#####GJ###################JG#####", "######I###################I######", "######I###################I######", "######I###################I######", "######II#################II######", "#######I#################I#######", "#######II###############II#######", "########II#############II########", "#########II###########II#########", "##########III#######III##########", "############IIIIJIIII############", "################G################", "#################################", "#################################", "#################################", "#################################", "#################################")
            .aisle("#####BHHHHHHHCCCCCCCHHHHHHHB#####", "#####BHHHHHHHCCCCCCCHHHHHHHB#####", "################F################", "################F################", "################F################", "################F################", "################F################", "################F################", "################F################", "################G################", "#############IIIJIII#############", "###########III#####III###########", "##########II#########II##########", "#########II###########II#########", "########II#############II########", "########I###############I########", "#######II###############II#######", "#######I#################I#######", "#######I#################I#######", "######GJ#################JG######", "#######I#################I#######", "#######I#################I#######", "#######II###############II#######", "########I###############I########", "########II#############II########", "#########II###########II#########", "##########II#########II##########", "###########III#####III###########", "#############IIIJIII#############", "################G################", "#################################", "#################################", "#################################", "#################################", "#################################", "#################################")
            .aisle("######BBHHHHHHHHCHHHHHHHHBB######", "######BBHHHHHHHHCHHHHHHHHBB######", "#################################", "#################################", "#################################", "#################################", "#################################", "#################################", "#################################", "#################################", "################G################", "##############IIJII##############", "############IIIIJIIII############", "###########III#####III###########", "##########II#########II##########", "#########II###########II#########", "#########II###########II#########", "########II#############II########", "########II#############II########", "#######GJJ#############JJG#######", "########II#############II########", "########II#############II########", "#########II###########II#########", "#########II###########II#########", "##########II#########II##########", "###########III#####III###########", "############IIIIJIIII############", "##############IIJII##############", "################G################", "#################################", "#################################", "#################################", "#################################", "#################################", "#################################", "#################################")
            .aisle("########BBHHHHHHCHHHHHHBB########", "########BBHHHHHHCHHHHHHBB########", "#################################", "#################################", "#################################", "#################################", "#################################", "#################################", "#################################", "#################################", "#################################", "################G################", "################G################", "##############IIJII##############", "############IIIIJIIII############", "###########IIIIIJIIIII###########", "###########IIII###IIII###########", "##########IIII#####IIII##########", "##########III#######III##########", "########GGJJJ#######JJJGG########", "##########III#######III##########", "##########IIII#####IIII##########", "###########IIII###IIII###########", "###########IIIIIJIIIII###########", "############IIIIJIIII############", "##############IIJII##############", "################G################", "################G################", "#################################", "#################################", "#################################", "#################################", "#################################", "#################################", "#################################", "#################################")
            .aisle("##########BBHHHHCHHHHBB##########", "##########BBHHHHCHHHHBB##########", "#################################", "#################################", "#################################", "#################################", "#################################", "#################################", "#################################", "#################################", "#################################", "#################################", "#################################", "################G################", "################G################", "################G################", "###############IJI###############", "##############IIJII##############", "#############IIIJIII#############", "##########GGGJJJJJJJGGG##########", "#############IIIJIII#############", "##############IIJII##############", "###############IJI###############", "################G################", "################G################", "################G################", "#################################", "#################################", "#################################", "#################################", "#################################", "#################################", "#################################", "#################################", "#################################", "#################################")
            .aisle("############BBBBCBBBB############", "############BBBBKBBBB############", "################F################", "################F################", "################F################", "################F################", "################F################", "################F################", "################F################", "################F################", "################F################", "################F################", "################F################", "################F################", "################F################", "################F################", "################G################", "################G################", "################G################", "#############GGGGGGG#############", "################G################", "################G################", "################G################", "#################################", "#################################", "#################################", "#################################", "#################################", "#################################", "#################################", "#################################", "#################################", "#################################", "#################################", "#################################", "#################################")
                .where('K', Predicates.controller(Predicates.blocks(definition.get())))
                .where('#', Predicates.any())
                .where("B", Predicates.blocks("gtceu:advanced_computer_casing")
                    .or(Predicates.abilities(PartAbility.EXPORT_ITEMS, PartAbility.EXPORT_FLUIDS, PartAbility.IMPORT_ITEMS, PartAbility.IMPORT_FLUIDS))
                    .or(Predicates.abilities(PartAbility.MAINTENANCE))
                    .or(Predicates.abilities(PartAbility.INPUT_LASER))
                )
                .where("C", Predicates.blocks("kubejs:stellar_powered_casing"))
                .where("F", Predicates.blocks("gtceu:pure_cosmic_matter_frame"))
                .where("G", Predicates.blocks("kubejs:supercritical_neutronium_casing"))
                .where("H", Predicates.blocks("gtceu:computer_casing"))
                .where("I", Predicates.blocks("kubejs:fusion_glass_mk2"))
                .where("J", Predicates.blocks("kubejs:fusion_casing_mk4"))
                .where("Z", Predicates.blocks("betterblockz:cyberlight_blockz_12"))
                .where("L", Predicates.blocks("betterblockz:cyberlight_blockz_9"))
                .where("M", Predicates.blocks("betterblockz:cyberlight_blockz_0"))
                .where("N", Predicates.blocks("betterblockz:cyberlight_alt_blockz_7"))
                .where("O", Predicates.blocks("betterblockz:cyberlight_blockz_7"))
                .where("P", Predicates.blocks("betterblockz:cyberlight_blockz_1"))
                .where("Q", Predicates.blocks("betterblockz:cyberlight_blockz_2"))
                .where("R", Predicates.blocks("betterblockz:cyberlight_blockz_6"))

        .build()
        )
        .sidedWorkableCasingModel('gtceu:block/casings/hpca/advanced_computer_casing', 'gtceu:block/multiblock/hpca')

})