GTCEuStartupEvents.registry('gtceu:recipe_type', event => {
    event.create('eternity_fusion')
        .category('multiblocks')
        .setEUIO('in')
        .setMaxIOSize(0, 0, 2, 1) // Max Item Inputs, Max Item Outputs, Max Fluid Inputs, Max Fluid Outputs
        .setProgressBar(GuiTextures.PROGRESS_BAR_FUSION, FillDirection.LEFT_TO_RIGHT)
        .setSound(GTSoundEntries.REPLICATOR)
})

GTCEuStartupEvents.registry('gtceu:machine', event => {
    event.create('eternity_fusion_reactor', 'multiblock')
        .rotationState(RotationState.ALL)
        .recipeType('eternity_fusion')
        .recipeModifiers([GTRecipeModifiers.OC_PERFECT_SUBTICK, GTRecipeModifiers.BATCH_MODE])
        .appearanceBlock(() => Block.getBlock('kubejs:eternity_fusion_machine_casing'))
        .pattern(definition => FactoryBlockPattern.start()
            .aisle("AAAAAAAAAAAAAAAAAAAAAAAAAAAAAAAAAAAAAAAAAAAAAAAAA", "AAAAAAAAAAAAAAAAAAAABBBBBBBBBAAAAAAAAAAAAAAAAAAAA", "AAAAAAAAAAAAAAAABBBBBBBBBBBBBBBBBAAAAAAAAAAAAAAAA", "AAAAAAAAAAAAAABBBBBBBBBBBBBBBBBBBBBAAAAAAAAAAAAAA", "AAAAAAAAAAAABBBBBBBBAAAAAAAAABBBBBBBBAAAAAAAAAAAA", "AAAAAAAAAABBBBBBBAAAAAAAAAAAAAAABBBBBBBAAAAAAAAAA", "AAAAAAAAABBBBBBAAAAAAAAAAAAAAAAAAABBBBBBAAAAAAAAA", "AAAAAAAABBBBBAAAAAAAAAAAAAAAAAAAAAAABBBBBAAAAAAAA", "AAAAAAABBBBBAAAAAAAAAAAAAAAAAAAAAAAAABBBBBAAAAAAA", "AAAAAABBBBBAAAAAAAAAAAAAAAAAAAAAAAAAAABBBBBAAAAAA", "AAAAABBBBBAAAAAAAAAAAAAAAAAAAAAAAAAAAAABBBBBAAAAA", "AAAAABBBBAAAAAAAAAAAAAAAAAAAAAAAAAAAAAAABBBBAAAAA", "AAAABBBBAAAAAAAAAAAAAAAAAAAAAAAAAAAAAAAAABBBBAAAA", "AAAABBBAAAAAAAAAAAAAAAAAAAAAAAAAAAAAAAAAAABBBAAAA", "AAABBBBAAAAAAAAAAAAAAAAAAAAAAAAAAAAAAAAAAABBBBAAA", "AAABBBAAAAAAAAAAAAAAAAAAAAAAAAAAAAAAAAAAAAABBBAAA", "AABBBBAAAAAAAAAAAAAAAAAAAAAAAAAAAAAAAAAAAAABBBBAA", "AABBBAAAAAAAAAAAAAAAAAAAAAAAAAAAAAAAAAAAAAAABBBAA", "AABBBAAAAAAAAAAAAAAAAAAAAAAAAAAAAAAAAAAAAAAABBBAA", "AABBBAAAAAAAAAAAAAAAAAAAAAAAAAAAAAAAAAAAAAAABBBAA", "ABBBAAAAAAAAAAAAAAAAAAAAAAAAAAAAAAAAAAAAAAAAABBBA", "ABBBAAAAAAAAAAAAAAAAAAAAAAAAAAAAAAAAAAAAAAAAABBBA", "ABBBAAAAAAAAAAAAAAAAAAAAAAAAAAAAAAAAAAAAAAAAABBBA", "ABBBAAAAAAAAAAAAAAAAAAABBBAAAAAAAAAAAAAAAAAAABBBA", "ABBBAAAAAAAAAAAAAAAAAAABBBAAAAAAAAAAAAAAAAAAABBBA", "ABBBAAAAAAAAAAAAAAAAAAABBBAAAAAAAAAAAAAAAAAAABBBA", "ABBBAAAAAAAAAAAAAAAAAAAAAAAAAAAAAAAAAAAAAAAAABBBA", "ABBBAAAAAAAAAAAAAAAAAAAAAAAAAAAAAAAAAAAAAAAAABBBA", "ABBBAAAAAAAAAAAAAAAAAAAAAAAAAAAAAAAAAAAAAAAAABBBA", "AABBBAAAAAAAAAAAAAAAAAAAAAAAAAAAAAAAAAAAAAAABBBAA", "AABBBAAAAAAAAAAAAAAAAAAAAAAAAAAAAAAAAAAAAAAABBBAA", "AABBBAAAAAAAAAAAAAAAAAAAAAAAAAAAAAAAAAAAAAAABBBAA", "AABBBBAAAAAAAAAAAAAAAAAAAAAAAAAAAAAAAAAAAAABBBBAA", "AAABBBAAAAAAAAAAAAAAAAAAAAAAAAAAAAAAAAAAAAABBBAAA", "AAABBBBAAAAAAAAAAAAAAAAAAAAAAAAAAAAAAAAAAABBBBAAA", "AAAABBBAAAAAAAAAAAAAAAAAAAAAAAAAAAAAAAAAAABBBAAAA", "AAAABBBBAAAAAAAAAAAAAAAAAAAAAAAAAAAAAAAAABBBBAAAA", "AAAAABBBBAAAAAAAAAAAAAAAAAAAAAAAAAAAAAAABBBBAAAAA", "AAAAABBBBBAAAAAAAAAAAAAAAAAAAAAAAAAAAAABBBBBAAAAA", "AAAAAABBBBBAAAAAAAAAAAAAAAAAAAAAAAAAAABBBBBAAAAAA", "AAAAAAABBBBBAAAAAAAAAAAAAAAAAAAAAAAAABBBBBAAAAAAA", "AAAAAAAABBBBBAAAAAAAAAAAAAAAAAAAAAAABBBBBAAAAAAAA", "AAAAAAAAABBBBBBAAAAAAAAAAAAAAAAAAABBBBBBAAAAAAAAA", "AAAAAAAAAABBBBBBBAAAAAAAAAAAAAAABBBBBBBAAAAAAAAAA", "AAAAAAAAAAAABBBBBBBBAAAAAAAAABBBBBBBBAAAAAAAAAAAA", "AAAAAAAAAAAAAABBBBBBBBBBBBBBBBBBBBBAAAAAAAAAAAAAA", "AAAAAAAAAAAAAAAABBBBBBBBBBBBBBBBBAAAAAAAAAAAAAAAA", "AAAAAAAAAAAAAAAAAAAABBBBBBBBBAAAAAAAAAAAAAAAAAAAA", "AAAAAAAAAAAAAAAAAAAAAAAAAAAAAAAAAAAAAAAAAAAAAAAAA")
            .aisle("AAAAAAAAAAAAAAAAAAAABBBBBBBBBAAAAAAAAAAAAAAAAAAAA", "AAAAAAAAAAAAAAAABBBBDDDDDDDDDBBBBAAAAAAAAAAAAAAAA", "AAAAAAAAAAAAAABBDDDDEEEEEEEEEDDDDBBAAAAAAAAAAAAAA", "AAAAAAAAAAAABBDDEEEEDDDDDDDDDEEEEDDBBAAAAAAAAAAAA", "AAAAAAAAAABBDDEEEDDDBBBBBBBBBDDDEEEDDBBAAAAAAAAAA", "AAAAAAAAABDDEEEDDBBBAAAFBFAAABBBDDEEEDDBAAAAAAAAA", "AAAAAAAABDEEEDDBBAAAAAAFBFAAAAAABBDDEEEDBAAAAAAAA", "AAAAAAABDEEEDBBAAAAAAAAFBFAAAAAAAABBDEEEDBAAAAAAA", "AAAAAABDEEEDBAAAAAAAAAAFBFAAAAAAAAAABDEEEDBAAAAAA", "AAAAABDEEEDBAAAAAAAAAAAFBFAAAAAAAAAAABDEEEDBAAAAA", "AAAABDEEEDBAAAAAAAAAAAAFBFAAAAAAAAAAAABDEEEDBAAAA", "AAAABDEEDBAAAAAAAAAAAAAFBFAAAAAAAAAAAAABDEEDBAAAA", "AAABDEEDBAAAAAAAAAAAAAAFBFAAAAAAAAAAAAAABDEEDBAAA", "AAABDEDBAAAAAAAAAAAAAAAFBFAAAAAAAAAAAAAAABDEDBAAA", "AABDEEDBAAAAAAAAAAAAAAAFBFAAAAAAAAAAAAAAABDEEDBAA", "AABDEDBAAAAAAAAAAAAAAAAFBFAAAAAAAAAAAAAAAABDEDBAA", "ABDEEDBAAAAAAAAAAAAAAAAFBFAAAAAAAAAAAAAAAABDEEDBA", "ABDEDBAAAAAAAAAAAAAAAAAFBFAAAAAAAAAAAAAAAAABDEDBA", "ABDEDBAAAAAAAAAAAAAAAAAFBFAAAAAAAAAAAAAAAAABDEDBA", "ABDEDBAAAAAAAAAAAAAAAAAFBFAAAAAAAAAAAAAAAAABDEDBA", "BDEDBAAAAAAAAAAAAAAAAAAFBFAAAAAAAAAAAAAAAAAABDEDB", "BDEDBAAAAAAAAAAAAAAAAAAFBFAAAAAAAAAAAAAAAAAABDEDB", "BDEDBAAAAAAAAAAAAAAAAAAFBFAAAAAAAAAAAAAAAAAABDEDB", "BDEDBFFFFFFFFFFFFFFFFFFBBBFFFFFFFFFFFFFFFFFFBDEDB", "BDEDBBBBBBBBBBBBBBBBBBBBEBBBBBBBBBBBBBBBBBBBBDEDB", "BDEDBFFFFFFFFFFFFFFFFFFBBBFFFFFFFFFFFFFFFFFFBDEDB", "BDEDBAAAAAAAAAAAAAAAAAAFBFAAAAAAAAAAAAAAAAAABDEDB", "BDEDBAAAAAAAAAAAAAAAAAAFBFAAAAAAAAAAAAAAAAAABDEDB", "BDEDBAAAAAAAAAAAAAAAAAAFBFAAAAAAAAAAAAAAAAAABDEDB", "ABDEDBAAAAAAAAAAAAAAAAAFBFAAAAAAAAAAAAAAAAABDEDBA", "ABDEDBAAAAAAAAAAAAAAAAAFBFAAAAAAAAAAAAAAAAABDEDBA", "ABDEDBAAAAAAAAAAAAAAAAAFBFAAAAAAAAAAAAAAAAABDEDBA", "ABDEEDBAAAAAAAAAAAAAAAAFBFAAAAAAAAAAAAAAAABDEEDBA", "AABDEDBAAAAAAAAAAAAAAAAFBFAAAAAAAAAAAAAAAABDEDBAA", "AABDEEDBAAAAAAAAAAAAAAAFBFAAAAAAAAAAAAAAABDEEDBAA", "AAABDEDBAAAAAAAAAAAAAAAFBFAAAAAAAAAAAAAAABDEDBAAA", "AAABDEEDBAAAAAAAAAAAAAAFBFAAAAAAAAAAAAAABDEEDBAAA", "AAAABDEEDBAAAAAAAAAAAAAFBFAAAAAAAAAAAAABDEEDBAAAA", "AAAABDEEEDBAAAAAAAAAAAAFBFAAAAAAAAAAAABDEEEDBAAAA", "AAAAABDEEEDBAAAAAAAAAAAFBFAAAAAAAAAAABDEEEDBAAAAA", "AAAAAABDEEEDBAAAAAAAAAAFBFAAAAAAAAAABDEEEDBAAAAAA", "AAAAAAABDEEEDBBAAAAAAAAFBFAAAAAAAABBDEEEDBAAAAAAA", "AAAAAAAABDEEEDDBBAAAAAAFBFAAAAAABBDDEEEDBAAAAAAAA", "AAAAAAAAABDDEEEDDBBBAAAFBFAAABBBDDEEEDDBAAAAAAAAA", "AAAAAAAAAABBDDEEEDDDBBBBBBBBBDDDEEEDDBBAAAAAAAAAA", "AAAAAAAAAAAABBDDEEEEDDDDDDDDDEEEEDDBBAAAAAAAAAAAA", "AAAAAAAAAAAAAABBDDDDEEEEEEEEEDDDDBBAAAAAAAAAAAAAA", "AAAAAAAAAAAAAAAABBBBDDDDDDDDDBBBBAAAAAAAAAAAAAAAA", "AAAAAAAAAAAAAAAAAAAABBBBBBBBBAAAAAAAAAAAAAAAAAAAA")
            .aisle("AAAAAAAAAAAAAAAAAAAAGGGGGGGGGAAAAAAAAAAAAAAAAAAAA", "AAAAAAAAAAAAAAAAGGGGDEEEEEEEDGGGGAAAAAAAAAAAAAAAA", "AAAAAAAAAAAAAAGGDEEDEEEEEEEEEDEEDGGAAAAAAAAAAAAAA", "AAAAAAAAAAAAGGDDEEEEDEEEEEEEDEEEEDDGGAAAAAAAAAAAA", "AAAAAAAAAAGGDDEEEDDDGGGGDGGGGDDDEEEDDGGAAAAAAAAAA", "AAAAAAAAAGEEEEEDDGGGAAAGDGAAAGGGDDEEEEEGAAAAAAAAA", "AAAAAAAAGEEEEDDGGAAAAAAGDGAAAAAAGGDDEEEEGAAAAAAAA", "AAAAAAAGEEEEDGGAAAAAAAAGDGAAAAAAAAGGDEEEEGAAAAAAA", "AAAAAAGEEEEDGAAAAAAAAAAGDGAAAAAAAAAAGDEEEEGAAAAAA", "AAAAAGEEEEDGAAAAAAAAAAAGDGAAAAAAAAAAAGDEEEEGAAAAA", "AAAAGEEEEDGAAAAAAAAAAAAGDGAAAAAAAAAAAAGDEEEEGAAAA", "AAAAGEEEDGAAAAAAAAAAAAAGDGAAAAAAAAAAAAAGDEEEGAAAA", "AAAGDEEDGAAAAAAAAAAAAAAGDGAAAAAAAAAAAAAAGDEEDGAAA", "AAAGDEDGAAAAAAAAAAAAAAAGDGAAAAAAAAAAAAAAAGDEDGAAA", "AAGDEEDGAAAAAAAAAAAAAAAGDGAAAAAAAAAAAAAAAGDEEDGAA", "AAGDEDGAAAAAAAAAAAAAAAAGDGAAAAAAAAAAAAAAAAGDEDGAA", "AGDEEDGAAAAAAAAAAAAAAAAGDGAAAAAAAAAAAAAAAAGDEEDGA", "AGEEDGAAAAAAAAAAAAAAAAAGDGAAAAAAAAAAAAAAAAAGDEEGA", "AGEEDGAAAAAAAAAAAAAAAAAGDGAAAAAAAAAAAAAAAAAGDEEGA", "AGDEDGAAAAAAAAAAAAAAAAAGDGAAAAAAAAAAAAAAAAAGDEDGA", "GDEDGAAAAAAAAAAAAAAAAAAGDGAAAAAAAAAAAAAAAAAAGDEDG", "GEEEGAAAAAAAAAAAAAAAAAAGDGAAAAAAAAAAAAAAAAAAGEEEG", "GEEEGAAAAAAAAAAAAAAAAAAGDGAAAAAAAAAAAAAAAAAAGEEEG", "GEEEGGGGGGGGGGGGGGGGGGGGDGGGGGGGGGGGGGGGGGGGGEEEG", "GEEEDDDDDDDDDDDDDDDDDDDDEDDDDDDDDDDDDDDDDDDDDEEEG", "GEEEGGGGGGGGGGGGGGGGGGGGDGGGGGGGGGGGGGGGGGGGGEEEG", "GEEEGAAAAAAAAAAAAAAAAAAGDGAAAAAAAAAAAAAAAAAAGEEEG", "GEEEGAAAAAAAAAAAAAAAAAAGDGAAAAAAAAAAAAAAAAAAGEEEG", "GDEDGAAAAAAAAAAAAAAAAAAGDGAAAAAAAAAAAAAAAAAAGDEDG", "AGDEDGAAAAAAAAAAAAAAAAAGDGAAAAAAAAAAAAAAAAAGDEDGA", "AGEEDGAAAAAAAAAAAAAAAAAGDGAAAAAAAAAAAAAAAAAGDEEGA", "AGEEDGAAAAAAAAAAAAAAAAAGDGAAAAAAAAAAAAAAAAAGDEEGA", "AGDEEDGAAAAAAAAAAAAAAAAGDGAAAAAAAAAAAAAAAAGDEEDGA", "AAGDEDGAAAAAAAAAAAAAAAAGDGAAAAAAAAAAAAAAAAGDEDGAA", "AAGDEEDGAAAAAAAAAAAAAAAGDGAAAAAAAAAAAAAAAGDEEDGAA", "AAAGDEDGAAAAAAAAAAAAAAAGDGAAAAAAAAAAAAAAAGDEDGAAA", "AAAGDEEDGAAAAAAAAAAAAAAGDGAAAAAAAAAAAAAAGEEEDGAAA", "AAAAGEEEDGAAAAAAAAAAAAAGDGAAAAAAAAAAAAAGEEEEGAAAA", "AAAAGEEEEDGAAAAAAAAAAAAGDGAAAAAAAAAAAAGEEEEEGAAAA", "AAAAAGEEEEDGAAAAAAAAAAAGDGAAAAAAAAAAAGEEEEEGAAAAA", "AAAAAAGEEEEDGAAAAAAAAAAGDGAAAAAAAAAAGEEEEEGAAAAAA", "AAAAAAAGEEEEDGGAAAAAAAAGDGAAAAAAAAGGEEEEEGAAAAAAA", "AAAAAAAAGEEEEDDGGAAAAAAGDGAAAAAAGGDDEEEEGAAAAAAAA", "AAAAAAAAAGEEEEEDDGGGAAAGDGAAAGGGDDEEEEEGAAAAAAAAA", "AAAAAAAAAAGGDDEEEDDDGGGGDGGGGDDDEEEDDGGAAAAAAAAAA", "AAAAAAAAAAAAGGDDEEEEDEEEEEEEDEEEEDDGGAAAAAAAAAAAA", "AAAAAAAAAAAAAAGGDEEDEEEEEEEEEDEEDGGAAAAAAAAAAAAAA", "AAAAAAAAAAAAAAAAGGGGDEEEEEEEDGGGGAAAAAAAAAAAAAAAA", "AAAAAAAAAAAAAAAAAAAAGGGGGGGGGAAAAAAAAAAAAAAAAAAAA")
            .aisle("AAAAAAAAAAAAAAAAAAAABBBBBBBBBAAAAAAAAAAAAAAAAAAAA", "AAAAAAAAAAAAAAAABBBBDDDDDDDDDBBBBAAAAAAAAAAAAAAAA", "AAAAAAAAAAAAAABBDDDDEEEEEEEEEDDDDBBAAAAAAAAAAAAAA", "AAAAAAAAAAAABBDDEEEEDDDDDDDDDEEEEDDBBAAAAAAAAAAAA", "AAAAAAAAAABBDDEEEDDDBBBBBBBBBDDDEEEDDBBAAAAAAAAAA", "AAAAAAAAABDDEEEDDBBBAAAFBFAAABBBDDEEEDDBAAAAAAAAA", "AAAAAAAABDEEEDDBBAAAAAAFBFAAAAAABBDDEEEDBAAAAAAAA", "AAAAAAABDEEEDBBAAAAAAAAFBFAAAAAAAABBDEEEDBAAAAAAA", "AAAAAABDEEEDBAAAAAAAAAAFBFAAAAAAAAAABDEEEDBAAAAAA", "AAAAABDEEEDBAAAAAAAAAAAFBFAAAAAAAAAAABDEEEDBAAAAA", "AAAABDEEEDBAAAAAAAAAAAAFBFAAAAAAAAAAAABDEEEDBAAAA", "AAAABDEEDBAAAAAAAAAAAAAFBFAAAAAAAAAAAAABDEEDBAAAA", "AAABDEEDBAAAAAAAAAAAAAAFBFAAAAAAAAAAAAAABDEEDBAAA", "AAABDEDBAAAAAAAAAAAAAAAFBFAAAAAAAAAAAAAAABDEDBAAA", "AABDEEDBAAAAAAAAAAAAAAAFBFAAAAAAAAAAAAAAABDEEDBAA", "AABDEDBAAAAAAAAAAAAAAAAFBFAAAAAAAAAAAAAAAABDEDBAA", "ABDEEDBAAAAAAAAAAAAAAAAFBFAAAAAAAAAAAAAAAABDEEDBA", "ABDEDBAAAAAAAAAAAAAAAAAFBFAAAAAAAAAAAAAAAAABDEDBA", "ABDEDBAAAAAAAAAAAAAAAAAFBFAAAAAAAAAAAAAAAAABDEDBA", "ABDEDBAAAAAAAAAAAAAAAAAFBFAAAAAAAAAAAAAAAAABDEDBA", "BDEDBAAAAAAAAAAAAAAAAAAFBFAAAAAAAAAAAAAAAAAABDEDB", "BDEDBAAAAAAAAAAAAAAAAAAFBFAAAAAAAAAAAAAAAAAABDEDB", "BDEDBAAAAAAAAAAAAAAAAAAFBFAAAAAAAAAAAAAAAAAABDEDB", "BDEDBFFFFFFFFFFFFFFFFFFBBBFFFFFFFFFFFFFFFFFFBDEDB", "BDEDBBBBBBBBBBBBBBBBBBBBEBBBBBBBBBBBBBBBBBBBBDEDB", "BDEDBFFFFFFFFFFFFFFFFFFBBBFFFFFFFFFFFFFFFFFFBDEDB", "BDEDBAAAAAAAAAAAAAAAAAAFBFAAAAAAAAAAAAAAAAAABDEDB", "BDEDBAAAAAAAAAAAAAAAAAAFBFAAAAAAAAAAAAAAAAAABDEDB", "BDEDBAAAAAAAAAAAAAAAAAAFBFAAAAAAAAAAAAAAAAAABDEDB", "ABDEDBAAAAAAAAAAAAAAAAAFBFAAAAAAAAAAAAAAAAABDEDBA", "ABDEDBAAAAAAAAAAAAAAAAAFBFAAAAAAAAAAAAAAAAABDEDBA", "ABDEDBAAAAAAAAAAAAAAAAAFBFAAAAAAAAAAAAAAAAABDEDBA", "ABDEEDBAAAAAAAAAAAAAAAAFBFAAAAAAAAAAAAAAAABDEEDBA", "AABDEDBAAAAAAAAAAAAAAAAFBFAAAAAAAAAAAAAAAABDEDBAA", "AABDEEDBAAAAAAAAAAAAAAAFBFAAAAAAAAAAAAAAABDEEDBAA", "AAABDEDBAAAAAAAAAAAAAAAFBFAAAAAAAAAAAAAAABDEDBAAA", "AAABDEEDBAAAAAAAAAAAAAAFBFAAAAAAAAAAAAAABDEEDBAAA", "AAAABDEEDBAAAAAAAAAAAAAFBFAAAAAAAAAAAAABDEEDBAAAA", "AAAABDEEEDBAAAAAAAAAAAAFBFAAAAAAAAAAAABDEEEDBAAAA", "AAAAABDEEEDBAAAAAAAAAAAFBFAAAAAAAAAAABDEEEDBAAAAA", "AAAAAABDEEEDBAAAAAAAAAAFBFAAAAAAAAAABDEEEDBAAAAAA", "AAAAAAABDEEEDBBAAAAAAAAFBFAAAAAAAABBDEEEDBAAAAAAA", "AAAAAAAABDEEEDDBBAAAAAAFBFAAAAAABBDDEEEDBAAAAAAAA", "AAAAAAAAABDDEEEDDBBBAAAFBFAAABBBDDEEEDDBAAAAAAAAA", "AAAAAAAAAABBDDEEEDDDBBBBBBBBBDDDEEEDDBBAAAAAAAAAA", "AAAAAAAAAAAABBDDEEEEDDDDDDDDDEEEEDDBBAAAAAAAAAAAA", "AAAAAAAAAAAAAABBDDDDEEEEEEEEEDDDDBBAAAAAAAAAAAAAA", "AAAAAAAAAAAAAAAABBBBDDDDDDDDDBBBBAAAAAAAAAAAAAAAA", "AAAAAAAAAAAAAAAAAAAABBBBBBBBBAAAAAAAAAAAAAAAAAAAA")
            .aisle("AAAAAAAAAAAAAAAAAAAAAAAAAAAAAAAAAAAAAAAAAAAAAAAAA", "AAAAAAAAAAAAAAAAAAAABBBBBBBBBAAAAAAAAAAAAAAAAAAAA", "AAAAAAAAAAAAAAAABBBBBBBBBBBBBBBBBAAAAAAAAAAAAAAAA", "AAAAAAAAAAAAAABBBBBBBBBBBBBBBBBBBBBAAAAAAAAAAAAAA", "AAAAAAAAAAAABBBBBBBBAAAAAAAAABBBBBBBBAAAAAAAAAAAA", "AAAAAAAAAABBBBBBBAAAAAAAAAAAAAAABBBBBBBAAAAAAAAAA", "AAAAAAAAABBBBBBAAAAAAAAAAAAAAAAAAABBBBBBAAAAAAAAA", "AAAAAAAABBBBBAAAAAAAAAAAAAAAAAAAAAAABBBBBAAAAAAAA", "AAAAAAABBBBBAAAAAAAAAAAAAAAAAAAAAAAAABBBBBAAAAAAA", "AAAAAABBBBBAAAAAAAAAAAAAAAAAAAAAAAAAAABBBBBAAAAAA", "AAAAABBBBBAAAAAAAAAAAAAAAAAAAAAAAAAAAAABBBBBAAAAA", "AAAAABBBBAAAAAAAAAAAAAAAAAAAAAAAAAAAAAAABBBBAAAAA", "AAAABBBBAAAAAAAAAAAAAAAAAAAAAAAAAAAAAAAAABBBBAAAA", "AAAABBBAAAAAAAAAAAAAAAAAAAAAAAAAAAAAAAAAAABBBAAAA", "AAABBBBAAAAAAAAAAAAAAAAAAAAAAAAAAAAAAAAAAABBBBAAA", "AAABBBAAAAAAAAAAAAAAAAAAAAAAAAAAAAAAAAAAAAABBBAAA", "AABBBBAAAAAAAAAAAAAAAAAAAAAAAAAAAAAAAAAAAAABBBBAA", "AABBBAAAAAAAAAAAAAAAAAAAAAAAAAAAAAAAAAAAAAAABBBAA", "AABBBAAAAAAAAAAAAAAAAAAAAAAAAAAAAAAAAAAAAAAABBBAA", "AABBBAAAAAAAAAAAAAAAAAAAAAAAAAAAAAAAAAAAAAAABBBAA", "ABBBAAAAAAAAAAAAAAAAAAAAAAAAAAAAAAAAAAAAAAAAABBBA", "ABBBAAAAAAAAAAAAAAAAAAAAAAAAAAAAAAAAAAAAAAAAABBBA", "ABBBAAAAAAAAAAAAAAAAAAAAAAAAAAAAAAAAAAAAAAAAABBBA", "ABBBAAAAAAAAAAAAAAAAAAABBBAAAAAAAAAAAAAAAAAAABBBA", "ABBBAAAAAAAAAAAAAAAAAAABHBAAAAAAAAAAAAAAAAAAABBBA", "ABBBAAAAAAAAAAAAAAAAAAABBBAAAAAAAAAAAAAAAAAAABBBA", "ABBBAAAAAAAAAAAAAAAAAAAAAAAAAAAAAAAAAAAAAAAAABBBA", "ABBBAAAAAAAAAAAAAAAAAAAAAAAAAAAAAAAAAAAAAAAAABBBA", "ABBBAAAAAAAAAAAAAAAAAAAAAAAAAAAAAAAAAAAAAAAAABBBA", "AABBBAAAAAAAAAAAAAAAAAAAAAAAAAAAAAAAAAAAAAAABBBAA", "AABBBAAAAAAAAAAAAAAAAAAAAAAAAAAAAAAAAAAAAAAABBBAA", "AABBBAAAAAAAAAAAAAAAAAAAAAAAAAAAAAAAAAAAAAAABBBAA", "AABBBBAAAAAAAAAAAAAAAAAAAAAAAAAAAAAAAAAAAAABBBBAA", "AAABBBAAAAAAAAAAAAAAAAAAAAAAAAAAAAAAAAAAAAABBBAAA", "AAABBBBAAAAAAAAAAAAAAAAAAAAAAAAAAAAAAAAAAABBBBAAA", "AAAABBBAAAAAAAAAAAAAAAAAAAAAAAAAAAAAAAAAAABBBAAAA", "AAAABBBBAAAAAAAAAAAAAAAAAAAAAAAAAAAAAAAAABBBBAAAA", "AAAAABBBBAAAAAAAAAAAAAAAAAAAAAAAAAAAAAAABBBBAAAAA", "AAAAABBBBBAAAAAAAAAAAAAAAAAAAAAAAAAAAAABBBBBAAAAA", "AAAAAABBBBBAAAAAAAAAAAAAAAAAAAAAAAAAAABBBBBAAAAAA", "AAAAAAABBBBBAAAAAAAAAAAAAAAAAAAAAAAAABBBBBAAAAAAA", "AAAAAAAABBBBBAAAAAAAAAAAAAAAAAAAAAAABBBBBAAAAAAAA", "AAAAAAAAABBBBBBAAAAAAAAAAAAAAAAAAABBBBBBAAAAAAAAA", "AAAAAAAAAABBBBBBBAAAAAAAAAAAAAAABBBBBBBAAAAAAAAAA", "AAAAAAAAAAAABBBBBBBBAAAAAAAAABBBBBBBBAAAAAAAAAAAA", "AAAAAAAAAAAAAABBBBBBBBBBBBBBBBBBBBBAAAAAAAAAAAAAA", "AAAAAAAAAAAAAAAABBBBBBBBBBBBBBBBBAAAAAAAAAAAAAAAA", "AAAAAAAAAAAAAAAAAAAABBBBBBBBBAAAAAAAAAAAAAAAAAAAA", "AAAAAAAAAAAAAAAAAAAAAAAAAAAAAAAAAAAAAAAAAAAAAAAAA")
                .where("H", Predicates.controller(Predicates.blocks(definition.get())))
                .where("A", Predicates.any())
                .where("D", Predicates.blocks("kubejs:eternity_fusion_coil_block"))
                .where("E", Predicates.blocks("kubejs:eternity_casing"))
                .where("F", Predicates.blocks("gtceu:eternity_frame"))
                .where("G", Predicates.blocks("kubejs:fusion_glass_mk2"))
                .where("B", Predicates.blocks("kubejs:eternity_fusion_machine_casing")
                    .setMinGlobalLimited(1500)
                    .or(Predicates.abilities(
                        PartAbility.IMPORT_ITEMS,
                        PartAbility.IMPORT_FLUIDS,
                        PartAbility.EXPORT_ITEMS,
                        PartAbility.EXPORT_FLUIDS,
                        PartAbility.INPUT_ENERGY,
                        PartAbility.INPUT_LASER
                    ))
                )
            .build()
        )
        .workableCasingModel("kubejs:block/fusion/eternity_fusion_machine_casing", 'gtceu:block/multiblock/fusion_reactor')
})